Workbook

Sheet RESUMEN
A1: 📊 DASHBOARD FINANCIERO v4.0
A3: MÉTRICAS PRINCIPALES
A5: Total Ingresos: | B5: =SUMIF(TRANSACCIONES!B:B,"INGRESO",TRANSACCIONES!I:I)
A6: Total Egresos: | B6: =SUMIF(TRANSACCIONES!B:B,"EGRESO",TRANSACCIONES!I:I)
A7: Balance: | B7: =B5-B6
A9: Total por Pagar: | B9: =CxP!B3
A10: Total por Cobrar: | B10: =CxC!B3
A12: Transacciones Totales: | B12: =COUNTA(TRANSACCIONES!A:A)-1
A14: ESTADO DEL SISTEMA
A16: Versión: | B16: 4.0
A17: Última actualización: | B17: =NOW()

Sheet TRANSACCIONES
A1: Fecha | B1: Tipo | C1: Categoría | D1: Subcategoría | E1: Descripción | F1: Entidad | G1: Cuenta | H1: Método Pago | I1: Monto | J1: Referencia | K1: Notas | L1: Estado | M1: IVA | N1: Fecha Vencimiento | O1: Número Factura | P1: Personal/Negocio
A2: 45962 | B2: EGRESO | C2: Operaciones | D2: Nómina | E2: Pago de salario - Noviembre 2025 | F2: Juan Pérez | G2: BAC Corriente | H2: Transferencia | I2: 500000 | J2: TRF-2025-001 | K2: Pago quincenal | L2: PAGADO | M2: 0 | P2: Negocio
A3: 45966 | B3: EGRESO | C3: Operaciones | D3: Proveedores | E3: Compra de materiales | F3: Proveedor XYZ | G3: BAC Corriente | H3: Transferencia | I3: 150000 | J3: FAC-001 | K3: Materiales proyecto A | L3: PENDIENTE | M3: 19500 | N3: 45981 | O3: FAC-2025-001 | P3: Negocio
A4: 45971 | B4: INGRESO | C4: Ventas | D4: Servicios | E4: Pago cliente por servicio | F4: Cliente ABC | G4: BAC Corriente | H4: SINPE | I4: 300000 | J4: SINPE-001 | K4: Servicio de consultoría | L4: POR COBRAR | M4: 39000 | N4: 45986 | O4: INV-2025-001 | P4: Negocio

Sheet CxP
A1: 💰 CUENTAS POR PAGAR
A3: Total Pendiente: | B3: =SUM(D6:D55)
A5: Fecha | B5: Descripción | C5: Entidad | D5: Monto | E5: Fecha Vencimiento | F5: Días Pendientes | G5: Estado | H5: Notas
A6: =IFERROR(INDEX(TRANSACCIONES!$A$2:$A$1000,SMALL(IF(UPPER(TRANSACCIONES!$L$2:$L$1000)="PENDIENTE",ROW(TRANSACCIONES!$L$2:$L$1000)-ROW(TRANSACCIONES!$L$2)+1),1)),"") | B6: =IFERROR(INDEX(TRANSACCIONES!$E$2:$E$1000,SMALL(IF(UPPER(TRANSACCIONES!$L$2:$L$1000)="PENDIENTE",ROW(TRANSACCIONES!$L$2:$L$1000)-ROW(TRANSACCIONES!$L$2)+1),1)),"") | C6: =IFERROR(INDEX(TRANSACCIONES!$F$2:$F$1000,SMALL(IF(UPPER(TRANSACCIONES!$L$2:$L$1000)="PENDIENTE",ROW(TRANSACCIONES!$L$2:$L$1000)-ROW(TRANSACCIONES!$L$2)+1),1)),"") | D6: =IFERROR(INDEX(TRANSACCIONES!$I$2:$I$1000,SMALL(IF(UPPER(TRANSACCIONES!$L$2:$L$1000)="PENDIENTE",ROW(TRANSACCIONES!$L$2:$L$1000)-ROW(TRANSACCIONES!$L$2)+1),1)),"") | E6: =IFERROR(INDEX(TRANSACCIONES!$N$2:$N$1000,SMALL(IF(UPPER(TRANSACCIONES!$L$2:$L$1000)="PENDIENTE",ROW(TRANSACCIONES!$L$2:$L$1000)-ROW(TRANSACCIONES!$L$2)+1),1)),"") | F6: =IF(A6="","",TODAY()-A6) | G6: =IF(A6="","",IF(E6<TODAY(),"VENCIDO",IF(E6<=TODAY()+7,"POR VENCER","AL DÍA"))) | H6: =IFERROR(INDEX(TRANSACCIONES!$K$2:$K$1000,SMALL(IF(UPPER(TRANSACCIONES!$L$2:$L$1000)="PENDIENTE",ROW(TRANSACCIONES!$L$2:$L$1000)-ROW(TRANSACCIONES!$L$2)+1),1)),"")
A7: =IFERROR(INDEX(TRANSACCIONES!$A$2:$A$1000,SMALL(IF(UPPER(TRANSACCIONES!$L$2:$L$1000)="PENDIENTE",ROW(TRANSACCIONES!$L$2:$L$1000)-ROW(TRANSACCIONES!$L$2)+1),2)),"") | B7: =IFERROR(INDEX(TRANSACCIONES!$E$2:$E$1000,SMALL(IF(UPPER(TRANSACCIONES!$L$2:$L$1000)="PENDIENTE",ROW(TRANSACCIONES!$L$2:$L$1000)-ROW(TRANSACCIONES!$L$2)+1),2)),"") | C7: =IFERROR(INDEX(TRANSACCIONES!$F$2:$F$1000,SMALL(IF(UPPER(TRANSACCIONES!$L$2:$L$1000)="PENDIENTE",ROW(TRANSACCIONES!$L$2:$L$1000)-ROW(TRANSACCIONES!$L$2)+1),2)),"") | D7: =IFERROR(INDEX(TRANSACCIONES!$I$2:$I$1000,SMALL(IF(UPPER(TRANSACCIONES!$L$2:$L$1000)="PENDIENTE",ROW(TRANSACCIONES!$L$2:$L$1000)-ROW(TRANSACCIONES!$L$2)+1),2)),"") | E7: =IFERROR(INDEX(TRANSACCIONES!$N$2:$N$1000,SMALL(IF(UPPER(TRANSACCIONES!$L$2:$L$1000)="PENDIENTE",ROW(TRANSACCIONES!$L$2:$L$1000)-ROW(TRANSACCIONES!$L$2)+1),2)),"") | F7: =IF(A7="","",TODAY()-A7) | G7: =IF(A7="","",IF(E7<TODAY(),"VENCIDO",IF(E7<=TODAY()+7,"POR VENCER","AL DÍA"))) | H7: =IFERROR(INDEX(TRANSACCIONES!$K$2:$K$1000,SMALL(IF(UPPER(TRANSACCIONES!$L$2:$L$1000)="PENDIENTE",ROW(TRANSACCIONES!$L$2:$L$1000)-ROW(TRANSACCIONES!$L$2)+1),2)),"")
A8: =IFERROR(INDEX(TRANSACCIONES!$A$2:$A$1000,SMALL(IF(UPPER(TRANSACCIONES!$L$2:$L$1000)="PENDIENTE",ROW(TRANSACCIONES!$L$2:$L$1000)-ROW(TRANSACCIONES!$L$2)+1),3)),"") | B8: =IFERROR(INDEX(TRANSACCIONES!$E$2:$E$1000,SMALL(IF(UPPER(TRANSACCIONES!$L$2:$L$1000)="PENDIENTE",ROW(TRANSACCIONES!$L$2:$L$1000)-ROW(TRANSACCIONES!$L$2)+1),3)),"") | C8: =IFERROR(INDEX(TRANSACCIONES!$F$2:$F$1000,SMALL(IF(UPPER(TRANSACCIONES!$L$2:$L$1000)="PENDIENTE",ROW(TRANSACCIONES!$L$2:$L$1000)-ROW(TRANSACCIONES!$L$2)+1),3)),"") | D8: =IFERROR(INDEX(TRANSACCIONES!$I$2:$I$1000,SMALL(IF(UPPER(TRANSACCIONES!$L$2:$L$1000)="PENDIENTE",ROW(TRANSACCIONES!$L$2:$L$1000)-ROW(TRANSACCIONES!$L$2)+1),3)),"") | E8: =IFERROR(INDEX(TRANSACCIONES!$N$2:$N$1000,SMALL(IF(UPPER(TRANSACCIONES!$L$2:$L$1000)="PENDIENTE",ROW(TRANSACCIONES!$L$2:$L$1000)-ROW(TRANSACCIONES!$L$2)+1),3)),"") | F8: =IF(A8="","",TODAY()-A8) | G8: =IF(A8="","",IF(E8<TODAY(),"VENCIDO",IF(E8<=TODAY()+7,"POR VENCER","AL DÍA"))) | H8: =IFERROR(INDEX(TRANSACCIONES!$K$2:$K$1000,SMALL(IF(UPPER(TRANSACCIONES!$L$2:$L$1000)="PENDIENTE",ROW(TRANSACCIONES!$L$2:$L$1000)-ROW(TRANSACCIONES!$L$2)+1),3)),"")
A9: =IFERROR(INDEX(TRANSACCIONES!$A$2:$A$1000,SMALL(IF(UPPER(TRANSACCIONES!$L$2:$L$1000)="PENDIENTE",ROW(TRANSACCIONES!$L$2:$L$1000)-ROW(TRANSACCIONES!$L$2)+1),4)),"") | B9: =IFERROR(INDEX(TRANSACCIONES!$E$2:$E$1000,SMALL(IF(UPPER(TRANSACCIONES!$L$2:$L$1000)="PENDIENTE",ROW(TRANSACCIONES!$L$2:$L$1000)-ROW(TRANSACCIONES!$L$2)+1),4)),"") | C9: =IFERROR(INDEX(TRANSACCIONES!$F$2:$F$1000,SMALL(IF(UPPER(TRANSACCIONES!$L$2:$L$1000)="PENDIENTE",ROW(TRANSACCIONES!$L$2:$L$1000)-ROW(TRANSACCIONES!$L$2)+1),4)),"") | D9: =IFERROR(INDEX(TRANSACCIONES!$I$2:$I$1000,SMALL(IF(UPPER(TRANSACCIONES!$L$2:$L$1000)="PENDIENTE",ROW(TRANSACCIONES!$L$2:$L$1000)-ROW(TRANSACCIONES!$L$2)+1),4)),"") | E9: =IFERROR(INDEX(TRANSACCIONES!$N$2:$N$1000,SMALL(IF(UPPER(TRANSACCIONES!$L$2:$L$1000)="PENDIENTE",ROW(TRANSACCIONES!$L$2:$L$1000)-ROW(TRANSACCIONES!$L$2)+1),4)),"") | F9: =IF(A9="","",TODAY()-A9) | G9: =IF(A9="","",IF(E9<TODAY(),"VENCIDO",IF(E9<=TODAY()+7,"POR VENCER","AL DÍA"))) | H9: =IFERROR(INDEX(TRANSACCIONES!$K$2:$K$1000,SMALL(IF(UPPER(TRANSACCIONES!$L$2:$L$1000)="PENDIENTE",ROW(TRANSACCIONES!$L$2:$L$1000)-ROW(TRANSACCIONES!$L$2)+1),4)),"")
A10: =IFERROR(INDEX(TRANSACCIONES!$A$2:$A$1000,SMALL(IF(UPPER(TRANSACCIONES!$L$2:$L$1000)="PENDIENTE",ROW(TRANSACCIONES!$L$2:$L$1000)-ROW(TRANSACCIONES!$L$2)+1),5)),"") | B10: =IFERROR(INDEX(TRANSACCIONES!$E$2:$E$1000,SMALL(IF(UPPER(TRANSACCIONES!$L$2:$L$1000)="PENDIENTE",ROW(TRANSACCIONES!$L$2:$L$1000)-ROW(TRANSACCIONES!$L$2)+1),5)),"") | C10: =IFERROR(INDEX(TRANSACCIONES!$F$2:$F$1000,SMALL(IF(UPPER(TRANSACCIONES!$L$2:$L$1000)="PENDIENTE",ROW(TRANSACCIONES!$L$2:$L$1000)-ROW(TRANSACCIONES!$L$2)+1),5)),"") | D10: =IFERROR(INDEX(TRANSACCIONES!$I$2:$I$1000,SMALL(IF(UPPER(TRANSACCIONES!$L$2:$L$1000)="PENDIENTE",ROW(TRANSACCIONES!$L$2:$L$1000)-ROW(TRANSACCIONES!$L$2)+1),5)),"") | E10: =IFERROR(INDEX(TRANSACCIONES!$N$2:$N$1000,SMALL(IF(UPPER(TRANSACCIONES!$L$2:$L$1000)="PENDIENTE",ROW(TRANSACCIONES!$L$2:$L$1000)-ROW(TRANSACCIONES!$L$2)+1),5)),"") | F10: =IF(A10="","",TODAY()-A10) | G10: =IF(A10="","",IF(E10<TODAY(),"VENCIDO",IF(E10<=TODAY()+7,"POR VENCER","AL DÍA"))) | H10: =IFERROR(INDEX(TRANSACCIONES!$K$2:$K$1000,SMALL(IF(UPPER(TRANSACCIONES!$L$2:$L$1000)="PENDIENTE",ROW(TRANSACCIONES!$L$2:$L$1000)-ROW(TRANSACCIONES!$L$2)+1),5)),"")
A11: =IFERROR(INDEX(TRANSACCIONES!$A$2:$A$1000,SMALL(IF(UPPER(TRANSACCIONES!$L$2:$L$1000)="PENDIENTE",ROW(TRANSACCIONES!$L$2:$L$1000)-ROW(TRANSACCIONES!$L$2)+1),6)),"") | B11: =IFERROR(INDEX(TRANSACCIONES!$E$2:$E$1000,SMALL(IF(UPPER(TRANSACCIONES!$L$2:$L$1000)="PENDIENTE",ROW(TRANSACCIONES!$L$2:$L$1000)-ROW(TRANSACCIONES!$L$2)+1),6)),"") | C11: =IFERROR(INDEX(TRANSACCIONES!$F$2:$F$1000,SMALL(IF(UPPER(TRANSACCIONES!$L$2:$L$1000)="PENDIENTE",ROW(TRANSACCIONES!$L$2:$L$1000)-ROW(TRANSACCIONES!$L$2)+1),6)),"") | D11: =IFERROR(INDEX(TRANSACCIONES!$I$2:$I$1000,SMALL(IF(UPPER(TRANSACCIONES!$L$2:$L$1000)="PENDIENTE",ROW(TRANSACCIONES!$L$2:$L$1000)-ROW(TRANSACCIONES!$L$2)+1),6)),"") | E11: =IFERROR(INDEX(TRANSACCIONES!$N$2:$N$1000,SMALL(IF(UPPER(TRANSACCIONES!$L$2:$L$1000)="PENDIENTE",ROW(TRANSACCIONES!$L$2:$L$1000)-ROW(TRANSACCIONES!$L$2)+1),6)),"") | F11: =IF(A11="","",TODAY()-A11) | G11: =IF(A11="","",IF(E11<TODAY(),"VENCIDO",IF(E11<=TODAY()+7,"POR VENCER","AL DÍA"))) | H11: =IFERROR(INDEX(TRANSACCIONES!$K$2:$K$1000,SMALL(IF(UPPER(TRANSACCIONES!$L$2:$L$1000)="PENDIENTE",ROW(TRANSACCIONES!$L$2:$L$1000)-ROW(TRANSACCIONES!$L$2)+1),6)),"")
A12: =IFERROR(INDEX(TRANSACCIONES!$A$2:$A$1000,SMALL(IF(UPPER(TRANSACCIONES!$L$2:$L$1000)="PENDIENTE",ROW(TRANSACCIONES!$L$2:$L$1000)-ROW(TRANSACCIONES!$L$2)+1),7)),"") | B12: =IFERROR(INDEX(TRANSACCIONES!$E$2:$E$1000,SMALL(IF(UPPER(TRANSACCIONES!$L$2:$L$1000)="PENDIENTE",ROW(TRANSACCIONES!$L$2:$L$1000)-ROW(TRANSACCIONES!$L$2)+1),7)),"") | C12: =IFERROR(INDEX(TRANSACCIONES!$F$2:$F$1000,SMALL(IF(UPPER(TRANSACCIONES!$L$2:$L$1000)="PENDIENTE",ROW(TRANSACCIONES!$L$2:$L$1000)-ROW(TRANSACCIONES!$L$2)+1),7)),"") | D12: =IFERROR(INDEX(TRANSACCIONES!$I$2:$I$1000,SMALL(IF(UPPER(TRANSACCIONES!$L$2:$L$1000)="PENDIENTE",ROW(TRANSACCIONES!$L$2:$L$1000)-ROW(TRANSACCIONES!$L$2)+1),7)),"") | E12: =IFERROR(INDEX(TRANSACCIONES!$N$2:$N$1000,SMALL(IF(UPPER(TRANSACCIONES!$L$2:$L$1000)="PENDIENTE",ROW(TRANSACCIONES!$L$2:$L$1000)-ROW(TRANSACCIONES!$L$2)+1),7)),"") | F12: =IF(A12="","",TODAY()-A12) | G12: =IF(A12="","",IF(E12<TODAY(),"VENCIDO",IF(E12<=TODAY()+7,"POR VENCER","AL DÍA"))) | H12: =IFERROR(INDEX(TRANSACCIONES!$K$2:$K$1000,SMALL(IF(UPPER(TRANSACCIONES!$L$2:$L$1000)="PENDIENTE",ROW(TRANSACCIONES!$L$2:$L$1000)-ROW(TRANSACCIONES!$L$2)+1),7)),"")
A13: =IFERROR(INDEX(TRANSACCIONES!$A$2:$A$1000,SMALL(IF(UPPER(TRANSACCIONES!$L$2:$L$1000)="PENDIENTE",ROW(TRANSACCIONES!$L$2:$L$1000)-ROW(TRANSACCIONES!$L$2)+1),8)),"") | B13: =IFERROR(INDEX(TRANSACCIONES!$E$2:$E$1000,SMALL(IF(UPPER(TRANSACCIONES!$L$2:$L$1000)="PENDIENTE",ROW(TRANSACCIONES!$L$2:$L$1000)-ROW(TRANSACCIONES!$L$2)+1),8)),"") | C13: =IFERROR(INDEX(TRANSACCIONES!$F$2:$F$1000,SMALL(IF(UPPER(TRANSACCIONES!$L$2:$L$1000)="PENDIENTE",ROW(TRANSACCIONES!$L$2:$L$1000)-ROW(TRANSACCIONES!$L$2)+1),8)),"") | D13: =IFERROR(INDEX(TRANSACCIONES!$I$2:$I$1000,SMALL(IF(UPPER(TRANSACCIONES!$L$2:$L$1000)="PENDIENTE",ROW(TRANSACCIONES!$L$2:$L$1000)-ROW(TRANSACCIONES!$L$2)+1),8)),"") | E13: =IFERROR(INDEX(TRANSACCIONES!$N$2:$N$1000,SMALL(IF(UPPER(TRANSACCIONES!$L$2:$L$1000)="PENDIENTE",ROW(TRANSACCIONES!$L$2:$L$1000)-ROW(TRANSACCIONES!$L$2)+1),8)),"") | F13: =IF(A13="","",TODAY()-A13) | G13: =IF(A13="","",IF(E13<TODAY(),"VENCIDO",IF(E13<=TODAY()+7,"POR VENCER","AL DÍA"))) | H13: =IFERROR(INDEX(TRANSACCIONES!$K$2:$K$1000,SMALL(IF(UPPER(TRANSACCIONES!$L$2:$L$1000)="PENDIENTE",ROW(TRANSACCIONES!$L$2:$L$1000)-ROW(TRANSACCIONES!$L$2)+1),8)),"")
A14: =IFERROR(INDEX(TRANSACCIONES!$A$2:$A$1000,SMALL(IF(UPPER(TRANSACCIONES!$L$2:$L$1000)="PENDIENTE",ROW(TRANSACCIONES!$L$2:$L$1000)-ROW(TRANSACCIONES!$L$2)+1),9)),"") | B14: =IFERROR(INDEX(TRANSACCIONES!$E$2:$E$1000,SMALL(IF(UPPER(TRANSACCIONES!$L$2:$L$1000)="PENDIENTE",ROW(TRANSACCIONES!$L$2:$L$1000)-ROW(TRANSACCIONES!$L$2)+1),9)),"") | C14: =IFERROR(INDEX(TRANSACCIONES!$F$2:$F$1000,SMALL(IF(UPPER(TRANSACCIONES!$L$2:$L$1000)="PENDIENTE",ROW(TRANSACCIONES!$L$2:$L$1000)-ROW(TRANSACCIONES!$L$2)+1),9)),"") | D14: =IFERROR(INDEX(TRANSACCIONES!$I$2:$I$1000,SMALL(IF(UPPER(TRANSACCIONES!$L$2:$L$1000)="PENDIENTE",ROW(TRANSACCIONES!$L$2:$L$1000)-ROW(TRANSACCIONES!$L$2)+1),9)),"") | E14: =IFERROR(INDEX(TRANSACCIONES!$N$2:$N$1000,SMALL(IF(UPPER(TRANSACCIONES!$L$2:$L$1000)="PENDIENTE",ROW(TRANSACCIONES!$L$2:$L$1000)-ROW(TRANSACCIONES!$L$2)+1),9)),"") | F14: =IF(A14="","",TODAY()-A14) | G14: =IF(A14="","",IF(E14<TODAY(),"VENCIDO",IF(E14<=TODAY()+7,"POR VENCER","AL DÍA"))) | H14: =IFERROR(INDEX(TRANSACCIONES!$K$2:$K$1000,SMALL(IF(UPPER(TRANSACCIONES!$L$2:$L$1000)="PENDIENTE",ROW(TRANSACCIONES!$L$2:$L$1000)-ROW(TRANSACCIONES!$L$2)+1),9)),"")
A15: =IFERROR(INDEX(TRANSACCIONES!$A$2:$A$1000,SMALL(IF(UPPER(TRANSACCIONES!$L$2:$L$1000)="PENDIENTE",ROW(TRANSACCIONES!$L$2:$L$1000)-ROW(TRANSACCIONES!$L$2)+1),10)),"") | B15: =IFERROR(INDEX(TRANSACCIONES!$E$2:$E$1000,SMALL(IF(UPPER(TRANSACCIONES!$L$2:$L$1000)="PENDIENTE",ROW(TRANSACCIONES!$L$2:$L$1000)-ROW(TRANSACCIONES!$L$2)+1),10)),"") | C15: =IFERROR(INDEX(TRANSACCIONES!$F$2:$F$1000,SMALL(IF(UPPER(TRANSACCIONES!$L$2:$L$1000)="PENDIENTE",ROW(TRANSACCIONES!$L$2:$L$1000)-ROW(TRANSACCIONES!$L$2)+1),10)),"") | D15: =IFERROR(INDEX(TRANSACCIONES!$I$2:$I$1000,SMALL(IF(UPPER(TRANSACCIONES!$L$2:$L$1000)="PENDIENTE",ROW(TRANSACCIONES!$L$2:$L$1000)-ROW(TRANSACCIONES!$L$2)+1),10)),"") | E15: =IFERROR(INDEX(TRANSACCIONES!$N$2:$N$1000,SMALL(IF(UPPER(TRANSACCIONES!$L$2:$L$1000)="PENDIENTE",ROW(TRANSACCIONES!$L$2:$L$1000)-ROW(TRANSACCIONES!$L$2)+1),10)),"") | F15: =IF(A15="","",TODAY()-A15) | G15: =IF(A15="","",IF(E15<TODAY(),"VENCIDO",IF(E15<=TODAY()+7,"POR VENCER","AL DÍA"))) | H15: =IFERROR(INDEX(TRANSACCIONES!$K$2:$K$1000,SMALL(IF(UPPER(TRANSACCIONES!$L$2:$L$1000)="PENDIENTE",ROW(TRANSACCIONES!$L$2:$L$1000)-ROW(TRANSACCIONES!$L$2)+1),10)),"")
A16: =IFERROR(INDEX(TRANSACCIONES!$A$2:$A$1000,SMALL(IF(UPPER(TRANSACCIONES!$L$2:$L$1000)="PENDIENTE",ROW(TRANSACCIONES!$L$2:$L$1000)-ROW(TRANSACCIONES!$L$2)+1),11)),"") | B16: =IFERROR(INDEX(TRANSACCIONES!$E$2:$E$1000,SMALL(IF(UPPER(TRANSACCIONES!$L$2:$L$1000)="PENDIENTE",ROW(TRANSACCIONES!$L$2:$L$1000)-ROW(TRANSACCIONES!$L$2)+1),11)),"") | C16: =IFERROR(INDEX(TRANSACCIONES!$F$2:$F$1000,SMALL(IF(UPPER(TRANSACCIONES!$L$2:$L$1000)="PENDIENTE",ROW(TRANSACCIONES!$L$2:$L$1000)-ROW(TRANSACCIONES!$L$2)+1),11)),"") | D16: =IFERROR(INDEX(TRANSACCIONES!$I$2:$I$1000,SMALL(IF(UPPER(TRANSACCIONES!$L$2:$L$1000)="PENDIENTE",ROW(TRANSACCIONES!$L$2:$L$1000)-ROW(TRANSACCIONES!$L$2)+1),11)),"") | E16: =IFERROR(INDEX(TRANSACCIONES!$N$2:$N$1000,SMALL(IF(UPPER(TRANSACCIONES!$L$2:$L$1000)="PENDIENTE",ROW(TRANSACCIONES!$L$2:$L$1000)-ROW(TRANSACCIONES!$L$2)+1),11)),"") | F16: =IF(A16="","",TODAY()-A16) | G16: =IF(A16="","",IF(E16<TODAY(),"VENCIDO",IF(E16<=TODAY()+7,"POR VENCER","AL DÍA"))) | H16: =IFERROR(INDEX(TRANSACCIONES!$K$2:$K$1000,SMALL(IF(UPPER(TRANSACCIONES!$L$2:$L$1000)="PENDIENTE",ROW(TRANSACCIONES!$L$2:$L$1000)-ROW(TRANSACCIONES!$L$2)+1),11)),"")
A17: =IFERROR(INDEX(TRANSACCIONES!$A$2:$A$1000,SMALL(IF(UPPER(TRANSACCIONES!$L$2:$L$1000)="PENDIENTE",ROW(TRANSACCIONES!$L$2:$L$1000)-ROW(TRANSACCIONES!$L$2)+1),12)),"") | B17: =IFERROR(INDEX(TRANSACCIONES!$E$2:$E$1000,SMALL(IF(UPPER(TRANSACCIONES!$L$2:$L$1000)="PENDIENTE",ROW(TRANSACCIONES!$L$2:$L$1000)-ROW(TRANSACCIONES!$L$2)+1),12)),"") | C17: =IFERROR(INDEX(TRANSACCIONES!$F$2:$F$1000,SMALL(IF(UPPER(TRANSACCIONES!$L$2:$L$1000)="PENDIENTE",ROW(TRANSACCIONES!$L$2:$L$1000)-ROW(TRANSACCIONES!$L$2)+1),12)),"") | D17: =IFERROR(INDEX(TRANSACCIONES!$I$2:$I$1000,SMALL(IF(UPPER(TRANSACCIONES!$L$2:$L$1000)="PENDIENTE",ROW(TRANSACCIONES!$L$2:$L$1000)-ROW(TRANSACCIONES!$L$2)+1),12)),"") | E17: =IFERROR(INDEX(TRANSACCIONES!$N$2:$N$1000,SMALL(IF(UPPER(TRANSACCIONES!$L$2:$L$1000)="PENDIENTE",ROW(TRANSACCIONES!$L$2:$L$1000)-ROW(TRANSACCIONES!$L$2)+1),12)),"") | F17: =IF(A17="","",TODAY()-A17) | G17: =IF(A17="","",IF(E17<TODAY(),"VENCIDO",IF(E17<=TODAY()+7,"POR VENCER","AL DÍA"))) | H17: =IFERROR(INDEX(TRANSACCIONES!$K$2:$K$1000,SMALL(IF(UPPER(TRANSACCIONES!$L$2:$L$1000)="PENDIENTE",ROW(TRANSACCIONES!$L$2:$L$1000)-ROW(TRANSACCIONES!$L$2)+1),12)),"")
A18: =IFERROR(INDEX(TRANSACCIONES!$A$2:$A$1000,SMALL(IF(UPPER(TRANSACCIONES!$L$2:$L$1000)="PENDIENTE",ROW(TRANSACCIONES!$L$2:$L$1000)-ROW(TRANSACCIONES!$L$2)+1),13)),"") | B18: =IFERROR(INDEX(TRANSACCIONES!$E$2:$E$1000,SMALL(IF(UPPER(TRANSACCIONES!$L$2:$L$1000)="PENDIENTE",ROW(TRANSACCIONES!$L$2:$L$1000)-ROW(TRANSACCIONES!$L$2)+1),13)),"") | C18: =IFERROR(INDEX(TRANSACCIONES!$F$2:$F$1000,SMALL(IF(UPPER(TRANSACCIONES!$L$2:$L$1000)="PENDIENTE",ROW(TRANSACCIONES!$L$2:$L$1000)-ROW(TRANSACCIONES!$L$2)+1),13)),"") | D18: =IFERROR(INDEX(TRANSACCIONES!$I$2:$I$1000,SMALL(IF(UPPER(TRANSACCIONES!$L$2:$L$1000)="PENDIENTE",ROW(TRANSACCIONES!$L$2:$L$1000)-ROW(TRANSACCIONES!$L$2)+1),13)),"") | E18: =IFERROR(INDEX(TRANSACCIONES!$N$2:$N$1000,SMALL(IF(UPPER(TRANSACCIONES!$L$2:$L$1000)="PENDIENTE",ROW(TRANSACCIONES!$L$2:$L$1000)-ROW(TRANSACCIONES!$L$2)+1),13)),"") | F18: =IF(A18="","",TODAY()-A18) | G18: =IF(A18="","",IF(E18<TODAY(),"VENCIDO",IF(E18<=TODAY()+7,"POR VENCER","AL DÍA"))) | H18: =IFERROR(INDEX(TRANSACCIONES!$K$2:$K$1000,SMALL(IF(UPPER(TRANSACCIONES!$L$2:$L$1000)="PENDIENTE",ROW(TRANSACCIONES!$L$2:$L$1000)-ROW(TRANSACCIONES!$L$2)+1),13)),"")
A19: =IFERROR(INDEX(TRANSACCIONES!$A$2:$A$1000,SMALL(IF(UPPER(TRANSACCIONES!$L$2:$L$1000)="PENDIENTE",ROW(TRANSACCIONES!$L$2:$L$1000)-ROW(TRANSACCIONES!$L$2)+1),14)),"") | B19: =IFERROR(INDEX(TRANSACCIONES!$E$2:$E$1000,SMALL(IF(UPPER(TRANSACCIONES!$L$2:$L$1000)="PENDIENTE",ROW(TRANSACCIONES!$L$2:$L$1000)-ROW(TRANSACCIONES!$L$2)+1),14)),"") | C19: =IFERROR(INDEX(TRANSACCIONES!$F$2:$F$1000,SMALL(IF(UPPER(TRANSACCIONES!$L$2:$L$1000)="PENDIENTE",ROW(TRANSACCIONES!$L$2:$L$1000)-ROW(TRANSACCIONES!$L$2)+1),14)),"") | D19: =IFERROR(INDEX(TRANSACCIONES!$I$2:$I$1000,SMALL(IF(UPPER(TRANSACCIONES!$L$2:$L$1000)="PENDIENTE",ROW(TRANSACCIONES!$L$2:$L$1000)-ROW(TRANSACCIONES!$L$2)+1),14)),"") | E19: =IFERROR(INDEX(TRANSACCIONES!$N$2:$N$1000,SMALL(IF(UPPER(TRANSACCIONES!$L$2:$L$1000)="PENDIENTE",ROW(TRANSACCIONES!$L$2:$L$1000)-ROW(TRANSACCIONES!$L$2)+1),14)),"") | F19: =IF(A19="","",TODAY()-A19) | G19: =IF(A19="","",IF(E19<TODAY(),"VENCIDO",IF(E19<=TODAY()+7,"POR VENCER","AL DÍA"))) | H19: =IFERROR(INDEX(TRANSACCIONES!$K$2:$K$1000,SMALL(IF(UPPER(TRANSACCIONES!$L$2:$L$1000)="PENDIENTE",ROW(TRANSACCIONES!$L$2:$L$1000)-ROW(TRANSACCIONES!$L$2)+1),14)),"")
A20: =IFERROR(INDEX(TRANSACCIONES!$A$2:$A$1000,SMALL(IF(UPPER(TRANSACCIONES!$L$2:$L$1000)="PENDIENTE",ROW(TRANSACCIONES!$L$2:$L$1000)-ROW(TRANSACCIONES!$L$2)+1),15)),"") | B20: =IFERROR(INDEX(TRANSACCIONES!$E$2:$E$1000,SMALL(IF(UPPER(TRANSACCIONES!$L$2:$L$1000)="PENDIENTE",ROW(TRANSACCIONES!$L$2:$L$1000)-ROW(TRANSACCIONES!$L$2)+1),15)),"") | C20: =IFERROR(INDEX(TRANSACCIONES!$F$2:$F$1000,SMALL(IF(UPPER(TRANSACCIONES!$L$2:$L$1000)="PENDIENTE",ROW(TRANSACCIONES!$L$2:$L$1000)-ROW(TRANSACCIONES!$L$2)+1),15)),"") | D20: =IFERROR(INDEX(TRANSACCIONES!$I$2:$I$1000,SMALL(IF(UPPER(TRANSACCIONES!$L$2:$L$1000)="PENDIENTE",ROW(TRANSACCIONES!$L$2:$L$1000)-ROW(TRANSACCIONES!$L$2)+1),15)),"") | E20: =IFERROR(INDEX(TRANSACCIONES!$N$2:$N$1000,SMALL(IF(UPPER(TRANSACCIONES!$L$2:$L$1000)="PENDIENTE",ROW(TRANSACCIONES!$L$2:$L$1000)-ROW(TRANSACCIONES!$L$2)+1),15)),"") | F20: =IF(A20="","",TODAY()-A20) | G20: =IF(A20="","",IF(E20<TODAY(),"VENCIDO",IF(E20<=TODAY()+7,"POR VENCER","AL DÍA"))) | H20: =IFERROR(INDEX(TRANSACCIONES!$K$2:$K$1000,SMALL(IF(UPPER(TRANSACCIONES!$L$2:$L$1000)="PENDIENTE",ROW(TRANSACCIONES!$L$2:$L$1000)-ROW(TRANSACCIONES!$L$2)+1),15)),"")
A21: =IFERROR(INDEX(TRANSACCIONES!$A$2:$A$1000,SMALL(IF(UPPER(TRANSACCIONES!$L$2:$L$1000)="PENDIENTE",ROW(TRANSACCIONES!$L$2:$L$1000)-ROW(TRANSACCIONES!$L$2)+1),16)),"") | B21: =IFERROR(INDEX(TRANSACCIONES!$E$2:$E$1000,SMALL(IF(UPPER(TRANSACCIONES!$L$2:$L$1000)="PENDIENTE",ROW(TRANSACCIONES!$L$2:$L$1000)-ROW(TRANSACCIONES!$L$2)+1),16)),"") | C21: =IFERROR(INDEX(TRANSACCIONES!$F$2:$F$1000,SMALL(IF(UPPER(TRANSACCIONES!$L$2:$L$1000)="PENDIENTE",ROW(TRANSACCIONES!$L$2:$L$1000)-ROW(TRANSACCIONES!$L$2)+1),16)),"") | D21: =IFERROR(INDEX(TRANSACCIONES!$I$2:$I$1000,SMALL(IF(UPPER(TRANSACCIONES!$L$2:$L$1000)="PENDIENTE",ROW(TRANSACCIONES!$L$2:$L$1000)-ROW(TRANSACCIONES!$L$2)+1),16)),"") | E21: =IFERROR(INDEX(TRANSACCIONES!$N$2:$N$1000,SMALL(IF(UPPER(TRANSACCIONES!$L$2:$L$1000)="PENDIENTE",ROW(TRANSACCIONES!$L$2:$L$1000)-ROW(TRANSACCIONES!$L$2)+1),16)),"") | F21: =IF(A21="","",TODAY()-A21) | G21: =IF(A21="","",IF(E21<TODAY(),"VENCIDO",IF(E21<=TODAY()+7,"POR VENCER","AL DÍA"))) | H21: =IFERROR(INDEX(TRANSACCIONES!$K$2:$K$1000,SMALL(IF(UPPER(TRANSACCIONES!$L$2:$L$1000)="PENDIENTE",ROW(TRANSACCIONES!$L$2:$L$1000)-ROW(TRANSACCIONES!$L$2)+1),16)),"")
A22: =IFERROR(INDEX(TRANSACCIONES!$A$2:$A$1000,SMALL(IF(UPPER(TRANSACCIONES!$L$2:$L$1000)="PENDIENTE",ROW(TRANSACCIONES!$L$2:$L$1000)-ROW(TRANSACCIONES!$L$2)+1),17)),"") | B22: =IFERROR(INDEX(TRANSACCIONES!$E$2:$E$1000,SMALL(IF(UPPER(TRANSACCIONES!$L$2:$L$1000)="PENDIENTE",ROW(TRANSACCIONES!$L$2:$L$1000)-ROW(TRANSACCIONES!$L$2)+1),17)),"") | C22: =IFERROR(INDEX(TRANSACCIONES!$F$2:$F$1000,SMALL(IF(UPPER(TRANSACCIONES!$L$2:$L$1000)="PENDIENTE",ROW(TRANSACCIONES!$L$2:$L$1000)-ROW(TRANSACCIONES!$L$2)+1),17)),"") | D22: =IFERROR(INDEX(TRANSACCIONES!$I$2:$I$1000,SMALL(IF(UPPER(TRANSACCIONES!$L$2:$L$1000)="PENDIENTE",ROW(TRANSACCIONES!$L$2:$L$1000)-ROW(TRANSACCIONES!$L$2)+1),17)),"") | E22: =IFERROR(INDEX(TRANSACCIONES!$N$2:$N$1000,SMALL(IF(UPPER(TRANSACCIONES!$L$2:$L$1000)="PENDIENTE",ROW(TRANSACCIONES!$L$2:$L$1000)-ROW(TRANSACCIONES!$L$2)+1),17)),"") | F22: =IF(A22="","",TODAY()-A22) | G22: =IF(A22="","",IF(E22<TODAY(),"VENCIDO",IF(E22<=TODAY()+7,"POR VENCER","AL DÍA"))) | H22: =IFERROR(INDEX(TRANSACCIONES!$K$2:$K$1000,SMALL(IF(UPPER(TRANSACCIONES!$L$2:$L$1000)="PENDIENTE",ROW(TRANSACCIONES!$L$2:$L$1000)-ROW(TRANSACCIONES!$L$2)+1),17)),"")
A23: =IFERROR(INDEX(TRANSACCIONES!$A$2:$A$1000,SMALL(IF(UPPER(TRANSACCIONES!$L$2:$L$1000)="PENDIENTE",ROW(TRANSACCIONES!$L$2:$L$1000)-ROW(TRANSACCIONES!$L$2)+1),18)),"") | B23: =IFERROR(INDEX(TRANSACCIONES!$E$2:$E$1000,SMALL(IF(UPPER(TRANSACCIONES!$L$2:$L$1000)="PENDIENTE",ROW(TRANSACCIONES!$L$2:$L$1000)-ROW(TRANSACCIONES!$L$2)+1),18)),"") | C23: =IFERROR(INDEX(TRANSACCIONES!$F$2:$F$1000,SMALL(IF(UPPER(TRANSACCIONES!$L$2:$L$1000)="PENDIENTE",ROW(TRANSACCIONES!$L$2:$L$1000)-ROW(TRANSACCIONES!$L$2)+1),18)),"") | D23: =IFERROR(INDEX(TRANSACCIONES!$I$2:$I$1000,SMALL(IF(UPPER(TRANSACCIONES!$L$2:$L$1000)="PENDIENTE",ROW(TRANSACCIONES!$L$2:$L$1000)-ROW(TRANSACCIONES!$L$2)+1),18)),"") | E23: =IFERROR(INDEX(TRANSACCIONES!$N$2:$N$1000,SMALL(IF(UPPER(TRANSACCIONES!$L$2:$L$1000)="PENDIENTE",ROW(TRANSACCIONES!$L$2:$L$1000)-ROW(TRANSACCIONES!$L$2)+1),18)),"") | F23: =IF(A23="","",TODAY()-A23) | G23: =IF(A23="","",IF(E23<TODAY(),"VENCIDO",IF(E23<=TODAY()+7,"POR VENCER","AL DÍA"))) | H23: =IFERROR(INDEX(TRANSACCIONES!$K$2:$K$1000,SMALL(IF(UPPER(TRANSACCIONES!$L$2:$L$1000)="PENDIENTE",ROW(TRANSACCIONES!$L$2:$L$1000)-ROW(TRANSACCIONES!$L$2)+1),18)),"")
A24: =IFERROR(INDEX(TRANSACCIONES!$A$2:$A$1000,SMALL(IF(UPPER(TRANSACCIONES!$L$2:$L$1000)="PENDIENTE",ROW(TRANSACCIONES!$L$2:$L$1000)-ROW(TRANSACCIONES!$L$2)+1),19)),"") | B24: =IFERROR(INDEX(TRANSACCIONES!$E$2:$E$1000,SMALL(IF(UPPER(TRANSACCIONES!$L$2:$L$1000)="PENDIENTE",ROW(TRANSACCIONES!$L$2:$L$1000)-ROW(TRANSACCIONES!$L$2)+1),19)),"") | C24: =IFERROR(INDEX(TRANSACCIONES!$F$2:$F$1000,SMALL(IF(UPPER(TRANSACCIONES!$L$2:$L$1000)="PENDIENTE",ROW(TRANSACCIONES!$L$2:$L$1000)-ROW(TRANSACCIONES!$L$2)+1),19)),"") | D24: =IFERROR(INDEX(TRANSACCIONES!$I$2:$I$1000,SMALL(IF(UPPER(TRANSACCIONES!$L$2:$L$1000)="PENDIENTE",ROW(TRANSACCIONES!$L$2:$L$1000)-ROW(TRANSACCIONES!$L$2)+1),19)),"") | E24: =IFERROR(INDEX(TRANSACCIONES!$N$2:$N$1000,SMALL(IF(UPPER(TRANSACCIONES!$L$2:$L$1000)="PENDIENTE",ROW(TRANSACCIONES!$L$2:$L$1000)-ROW(TRANSACCIONES!$L$2)+1),19)),"") | F24: =IF(A24="","",TODAY()-A24) | G24: =IF(A24="","",IF(E24<TODAY(),"VENCIDO",IF(E24<=TODAY()+7,"POR VENCER","AL DÍA"))) | H24: =IFERROR(INDEX(TRANSACCIONES!$K$2:$K$1000,SMALL(IF(UPPER(TRANSACCIONES!$L$2:$L$1000)="PENDIENTE",ROW(TRANSACCIONES!$L$2:$L$1000)-ROW(TRANSACCIONES!$L$2)+1),19)),"")
A25: =IFERROR(INDEX(TRANSACCIONES!$A$2:$A$1000,SMALL(IF(UPPER(TRANSACCIONES!$L$2:$L$1000)="PENDIENTE",ROW(TRANSACCIONES!$L$2:$L$1000)-ROW(TRANSACCIONES!$L$2)+1),20)),"") | B25: =IFERROR(INDEX(TRANSACCIONES!$E$2:$E$1000,SMALL(IF(UPPER(TRANSACCIONES!$L$2:$L$1000)="PENDIENTE",ROW(TRANSACCIONES!$L$2:$L$1000)-ROW(TRANSACCIONES!$L$2)+1),20)),"") | C25: =IFERROR(INDEX(TRANSACCIONES!$F$2:$F$1000,SMALL(IF(UPPER(TRANSACCIONES!$L$2:$L$1000)="PENDIENTE",ROW(TRANSACCIONES!$L$2:$L$1000)-ROW(TRANSACCIONES!$L$2)+1),20)),"") | D25: =IFERROR(INDEX(TRANSACCIONES!$I$2:$I$1000,SMALL(IF(UPPER(TRANSACCIONES!$L$2:$L$1000)="PENDIENTE",ROW(TRANSACCIONES!$L$2:$L$1000)-ROW(TRANSACCIONES!$L$2)+1),20)),"") | E25: =IFERROR(INDEX(TRANSACCIONES!$N$2:$N$1000,SMALL(IF(UPPER(TRANSACCIONES!$L$2:$L$1000)="PENDIENTE",ROW(TRANSACCIONES!$L$2:$L$1000)-ROW(TRANSACCIONES!$L$2)+1),20)),"") | F25: =IF(A25="","",TODAY()-A25) | G25: =IF(A25="","",IF(E25<TODAY(),"VENCIDO",IF(E25<=TODAY()+7,"POR VENCER","AL DÍA"))) | H25: =IFERROR(INDEX(TRANSACCIONES!$K$2:$K$1000,SMALL(IF(UPPER(TRANSACCIONES!$L$2:$L$1000)="PENDIENTE",ROW(TRANSACCIONES!$L$2:$L$1000)-ROW(TRANSACCIONES!$L$2)+1),20)),"")
A26: =IFERROR(INDEX(TRANSACCIONES!$A$2:$A$1000,SMALL(IF(UPPER(TRANSACCIONES!$L$2:$L$1000)="PENDIENTE",ROW(TRANSACCIONES!$L$2:$L$1000)-ROW(TRANSACCIONES!$L$2)+1),21)),"") | B26: =IFERROR(INDEX(TRANSACCIONES!$E$2:$E$1000,SMALL(IF(UPPER(TRANSACCIONES!$L$2:$L$1000)="PENDIENTE",ROW(TRANSACCIONES!$L$2:$L$1000)-ROW(TRANSACCIONES!$L$2)+1),21)),"") | C26: =IFERROR(INDEX(TRANSACCIONES!$F$2:$F$1000,SMALL(IF(UPPER(TRANSACCIONES!$L$2:$L$1000)="PENDIENTE",ROW(TRANSACCIONES!$L$2:$L$1000)-ROW(TRANSACCIONES!$L$2)+1),21)),"") | D26: =IFERROR(INDEX(TRANSACCIONES!$I$2:$I$1000,SMALL(IF(UPPER(TRANSACCIONES!$L$2:$L$1000)="PENDIENTE",ROW(TRANSACCIONES!$L$2:$L$1000)-ROW(TRANSACCIONES!$L$2)+1),21)),"") | E26: =IFERROR(INDEX(TRANSACCIONES!$N$2:$N$1000,SMALL(IF(UPPER(TRANSACCIONES!$L$2:$L$1000)="PENDIENTE",ROW(TRANSACCIONES!$L$2:$L$1000)-ROW(TRANSACCIONES!$L$2)+1),21)),"") | F26: =IF(A26="","",TODAY()-A26) | G26: =IF(A26="","",IF(E26<TODAY(),"VENCIDO",IF(E26<=TODAY()+7,"POR VENCER","AL DÍA"))) | H26: =IFERROR(INDEX(TRANSACCIONES!$K$2:$K$1000,SMALL(IF(UPPER(TRANSACCIONES!$L$2:$L$1000)="PENDIENTE",ROW(TRANSACCIONES!$L$2:$L$1000)-ROW(TRANSACCIONES!$L$2)+1),21)),"")
A27: =IFERROR(INDEX(TRANSACCIONES!$A$2:$A$1000,SMALL(IF(UPPER(TRANSACCIONES!$L$2:$L$1000)="PENDIENTE",ROW(TRANSACCIONES!$L$2:$L$1000)-ROW(TRANSACCIONES!$L$2)+1),22)),"") | B27: =IFERROR(INDEX(TRANSACCIONES!$E$2:$E$1000,SMALL(IF(UPPER(TRANSACCIONES!$L$2:$L$1000)="PENDIENTE",ROW(TRANSACCIONES!$L$2:$L$1000)-ROW(TRANSACCIONES!$L$2)+1),22)),"") | C27: =IFERROR(INDEX(TRANSACCIONES!$F$2:$F$1000,SMALL(IF(UPPER(TRANSACCIONES!$L$2:$L$1000)="PENDIENTE",ROW(TRANSACCIONES!$L$2:$L$1000)-ROW(TRANSACCIONES!$L$2)+1),22)),"") | D27: =IFERROR(INDEX(TRANSACCIONES!$I$2:$I$1000,SMALL(IF(UPPER(TRANSACCIONES!$L$2:$L$1000)="PENDIENTE",ROW(TRANSACCIONES!$L$2:$L$1000)-ROW(TRANSACCIONES!$L$2)+1),22)),"") | E27: =IFERROR(INDEX(TRANSACCIONES!$N$2:$N$1000,SMALL(IF(UPPER(TRANSACCIONES!$L$2:$L$1000)="PENDIENTE",ROW(TRANSACCIONES!$L$2:$L$1000)-ROW(TRANSACCIONES!$L$2)+1),22)),"") | F27: =IF(A27="","",TODAY()-A27) | G27: =IF(A27="","",IF(E27<TODAY(),"VENCIDO",IF(E27<=TODAY()+7,"POR VENCER","AL DÍA"))) | H27: =IFERROR(INDEX(TRANSACCIONES!$K$2:$K$1000,SMALL(IF(UPPER(TRANSACCIONES!$L$2:$L$1000)="PENDIENTE",ROW(TRANSACCIONES!$L$2:$L$1000)-ROW(TRANSACCIONES!$L$2)+1),22)),"")
A28: =IFERROR(INDEX(TRANSACCIONES!$A$2:$A$1000,SMALL(IF(UPPER(TRANSACCIONES!$L$2:$L$1000)="PENDIENTE",ROW(TRANSACCIONES!$L$2:$L$1000)-ROW(TRANSACCIONES!$L$2)+1),23)),"") | B28: =IFERROR(INDEX(TRANSACCIONES!$E$2:$E$1000,SMALL(IF(UPPER(TRANSACCIONES!$L$2:$L$1000)="PENDIENTE",ROW(TRANSACCIONES!$L$2:$L$1000)-ROW(TRANSACCIONES!$L$2)+1),23)),"") | C28: =IFERROR(INDEX(TRANSACCIONES!$F$2:$F$1000,SMALL(IF(UPPER(TRANSACCIONES!$L$2:$L$1000)="PENDIENTE",ROW(TRANSACCIONES!$L$2:$L$1000)-ROW(TRANSACCIONES!$L$2)+1),23)),"") | D28: =IFERROR(INDEX(TRANSACCIONES!$I$2:$I$1000,SMALL(IF(UPPER(TRANSACCIONES!$L$2:$L$1000)="PENDIENTE",ROW(TRANSACCIONES!$L$2:$L$1000)-ROW(TRANSACCIONES!$L$2)+1),23)),"") | E28: =IFERROR(INDEX(TRANSACCIONES!$N$2:$N$1000,SMALL(IF(UPPER(TRANSACCIONES!$L$2:$L$1000)="PENDIENTE",ROW(TRANSACCIONES!$L$2:$L$1000)-ROW(TRANSACCIONES!$L$2)+1),23)),"") | F28: =IF(A28="","",TODAY()-A28) | G28: =IF(A28="","",IF(E28<TODAY(),"VENCIDO",IF(E28<=TODAY()+7,"POR VENCER","AL DÍA"))) | H28: =IFERROR(INDEX(TRANSACCIONES!$K$2:$K$1000,SMALL(IF(UPPER(TRANSACCIONES!$L$2:$L$1000)="PENDIENTE",ROW(TRANSACCIONES!$L$2:$L$1000)-ROW(TRANSACCIONES!$L$2)+1),23)),"")
A29: =IFERROR(INDEX(TRANSACCIONES!$A$2:$A$1000,SMALL(IF(UPPER(TRANSACCIONES!$L$2:$L$1000)="PENDIENTE",ROW(TRANSACCIONES!$L$2:$L$1000)-ROW(TRANSACCIONES!$L$2)+1),24)),"") | B29: =IFERROR(INDEX(TRANSACCIONES!$E$2:$E$1000,SMALL(IF(UPPER(TRANSACCIONES!$L$2:$L$1000)="PENDIENTE",ROW(TRANSACCIONES!$L$2:$L$1000)-ROW(TRANSACCIONES!$L$2)+1),24)),"") | C29: =IFERROR(INDEX(TRANSACCIONES!$F$2:$F$1000,SMALL(IF(UPPER(TRANSACCIONES!$L$2:$L$1000)="PENDIENTE",ROW(TRANSACCIONES!$L$2:$L$1000)-ROW(TRANSACCIONES!$L$2)+1),24)),"") | D29: =IFERROR(INDEX(TRANSACCIONES!$I$2:$I$1000,SMALL(IF(UPPER(TRANSACCIONES!$L$2:$L$1000)="PENDIENTE",ROW(TRANSACCIONES!$L$2:$L$1000)-ROW(TRANSACCIONES!$L$2)+1),24)),"") | E29: =IFERROR(INDEX(TRANSACCIONES!$N$2:$N$1000,SMALL(IF(UPPER(TRANSACCIONES!$L$2:$L$1000)="PENDIENTE",ROW(TRANSACCIONES!$L$2:$L$1000)-ROW(TRANSACCIONES!$L$2)+1),24)),"") | F29: =IF(A29="","",TODAY()-A29) | G29: =IF(A29="","",IF(E29<TODAY(),"VENCIDO",IF(E29<=TODAY()+7,"POR VENCER","AL DÍA"))) | H29: =IFERROR(INDEX(TRANSACCIONES!$K$2:$K$1000,SMALL(IF(UPPER(TRANSACCIONES!$L$2:$L$1000)="PENDIENTE",ROW(TRANSACCIONES!$L$2:$L$1000)-ROW(TRANSACCIONES!$L$2)+1),24)),"")
A30: =IFERROR(INDEX(TRANSACCIONES!$A$2:$A$1000,SMALL(IF(UPPER(TRANSACCIONES!$L$2:$L$1000)="PENDIENTE",ROW(TRANSACCIONES!$L$2:$L$1000)-ROW(TRANSACCIONES!$L$2)+1),25)),"") | B30: =IFERROR(INDEX(TRANSACCIONES!$E$2:$E$1000,SMALL(IF(UPPER(TRANSACCIONES!$L$2:$L$1000)="PENDIENTE",ROW(TRANSACCIONES!$L$2:$L$1000)-ROW(TRANSACCIONES!$L$2)+1),25)),"") | C30: =IFERROR(INDEX(TRANSACCIONES!$F$2:$F$1000,SMALL(IF(UPPER(TRANSACCIONES!$L$2:$L$1000)="PENDIENTE",ROW(TRANSACCIONES!$L$2:$L$1000)-ROW(TRANSACCIONES!$L$2)+1),25)),"") | D30: =IFERROR(INDEX(TRANSACCIONES!$I$2:$I$1000,SMALL(IF(UPPER(TRANSACCIONES!$L$2:$L$1000)="PENDIENTE",ROW(TRANSACCIONES!$L$2:$L$1000)-ROW(TRANSACCIONES!$L$2)+1),25)),"") | E30: =IFERROR(INDEX(TRANSACCIONES!$N$2:$N$1000,SMALL(IF(UPPER(TRANSACCIONES!$L$2:$L$1000)="PENDIENTE",ROW(TRANSACCIONES!$L$2:$L$1000)-ROW(TRANSACCIONES!$L$2)+1),25)),"") | F30: =IF(A30="","",TODAY()-A30) | G30: =IF(A30="","",IF(E30<TODAY(),"VENCIDO",IF(E30<=TODAY()+7,"POR VENCER","AL DÍA"))) | H30: =IFERROR(INDEX(TRANSACCIONES!$K$2:$K$1000,SMALL(IF(UPPER(TRANSACCIONES!$L$2:$L$1000)="PENDIENTE",ROW(TRANSACCIONES!$L$2:$L$1000)-ROW(TRANSACCIONES!$L$2)+1),25)),"")
A31: =IFERROR(INDEX(TRANSACCIONES!$A$2:$A$1000,SMALL(IF(UPPER(TRANSACCIONES!$L$2:$L$1000)="PENDIENTE",ROW(TRANSACCIONES!$L$2:$L$1000)-ROW(TRANSACCIONES!$L$2)+1),26)),"") | B31: =IFERROR(INDEX(TRANSACCIONES!$E$2:$E$1000,SMALL(IF(UPPER(TRANSACCIONES!$L$2:$L$1000)="PENDIENTE",ROW(TRANSACCIONES!$L$2:$L$1000)-ROW(TRANSACCIONES!$L$2)+1),26)),"") | C31: =IFERROR(INDEX(TRANSACCIONES!$F$2:$F$1000,SMALL(IF(UPPER(TRANSACCIONES!$L$2:$L$1000)="PENDIENTE",ROW(TRANSACCIONES!$L$2:$L$1000)-ROW(TRANSACCIONES!$L$2)+1),26)),"") | D31: =IFERROR(INDEX(TRANSACCIONES!$I$2:$I$1000,SMALL(IF(UPPER(TRANSACCIONES!$L$2:$L$1000)="PENDIENTE",ROW(TRANSACCIONES!$L$2:$L$1000)-ROW(TRANSACCIONES!$L$2)+1),26)),"") | E31: =IFERROR(INDEX(TRANSACCIONES!$N$2:$N$1000,SMALL(IF(UPPER(TRANSACCIONES!$L$2:$L$1000)="PENDIENTE",ROW(TRANSACCIONES!$L$2:$L$1000)-ROW(TRANSACCIONES!$L$2)+1),26)),"") | F31: =IF(A31="","",TODAY()-A31) | G31: =IF(A31="","",IF(E31<TODAY(),"VENCIDO",IF(E31<=TODAY()+7,"POR VENCER","AL DÍA"))) | H31: =IFERROR(INDEX(TRANSACCIONES!$K$2:$K$1000,SMALL(IF(UPPER(TRANSACCIONES!$L$2:$L$1000)="PENDIENTE",ROW(TRANSACCIONES!$L$2:$L$1000)-ROW(TRANSACCIONES!$L$2)+1),26)),"")
A32: =IFERROR(INDEX(TRANSACCIONES!$A$2:$A$1000,SMALL(IF(UPPER(TRANSACCIONES!$L$2:$L$1000)="PENDIENTE",ROW(TRANSACCIONES!$L$2:$L$1000)-ROW(TRANSACCIONES!$L$2)+1),27)),"") | B32: =IFERROR(INDEX(TRANSACCIONES!$E$2:$E$1000,SMALL(IF(UPPER(TRANSACCIONES!$L$2:$L$1000)="PENDIENTE",ROW(TRANSACCIONES!$L$2:$L$1000)-ROW(TRANSACCIONES!$L$2)+1),27)),"") | C32: =IFERROR(INDEX(TRANSACCIONES!$F$2:$F$1000,SMALL(IF(UPPER(TRANSACCIONES!$L$2:$L$1000)="PENDIENTE",ROW(TRANSACCIONES!$L$2:$L$1000)-ROW(TRANSACCIONES!$L$2)+1),27)),"") | D32: =IFERROR(INDEX(TRANSACCIONES!$I$2:$I$1000,SMALL(IF(UPPER(TRANSACCIONES!$L$2:$L$1000)="PENDIENTE",ROW(TRANSACCIONES!$L$2:$L$1000)-ROW(TRANSACCIONES!$L$2)+1),27)),"") | E32: =IFERROR(INDEX(TRANSACCIONES!$N$2:$N$1000,SMALL(IF(UPPER(TRANSACCIONES!$L$2:$L$1000)="PENDIENTE",ROW(TRANSACCIONES!$L$2:$L$1000)-ROW(TRANSACCIONES!$L$2)+1),27)),"") | F32: =IF(A32="","",TODAY()-A32) | G32: =IF(A32="","",IF(E32<TODAY(),"VENCIDO",IF(E32<=TODAY()+7,"POR VENCER","AL DÍA"))) | H32: =IFERROR(INDEX(TRANSACCIONES!$K$2:$K$1000,SMALL(IF(UPPER(TRANSACCIONES!$L$2:$L$1000)="PENDIENTE",ROW(TRANSACCIONES!$L$2:$L$1000)-ROW(TRANSACCIONES!$L$2)+1),27)),"")
A33: =IFERROR(INDEX(TRANSACCIONES!$A$2:$A$1000,SMALL(IF(UPPER(TRANSACCIONES!$L$2:$L$1000)="PENDIENTE",ROW(TRANSACCIONES!$L$2:$L$1000)-ROW(TRANSACCIONES!$L$2)+1),28)),"") | B33: =IFERROR(INDEX(TRANSACCIONES!$E$2:$E$1000,SMALL(IF(UPPER(TRANSACCIONES!$L$2:$L$1000)="PENDIENTE",ROW(TRANSACCIONES!$L$2:$L$1000)-ROW(TRANSACCIONES!$L$2)+1),28)),"") | C33: =IFERROR(INDEX(TRANSACCIONES!$F$2:$F$1000,SMALL(IF(UPPER(TRANSACCIONES!$L$2:$L$1000)="PENDIENTE",ROW(TRANSACCIONES!$L$2:$L$1000)-ROW(TRANSACCIONES!$L$2)+1),28)),"") | D33: =IFERROR(INDEX(TRANSACCIONES!$I$2:$I$1000,SMALL(IF(UPPER(TRANSACCIONES!$L$2:$L$1000)="PENDIENTE",ROW(TRANSACCIONES!$L$2:$L$1000)-ROW(TRANSACCIONES!$L$2)+1),28)),"") | E33: =IFERROR(INDEX(TRANSACCIONES!$N$2:$N$1000,SMALL(IF(UPPER(TRANSACCIONES!$L$2:$L$1000)="PENDIENTE",ROW(TRANSACCIONES!$L$2:$L$1000)-ROW(TRANSACCIONES!$L$2)+1),28)),"") | F33: =IF(A33="","",TODAY()-A33) | G33: =IF(A33="","",IF(E33<TODAY(),"VENCIDO",IF(E33<=TODAY()+7,"POR VENCER","AL DÍA"))) | H33: =IFERROR(INDEX(TRANSACCIONES!$K$2:$K$1000,SMALL(IF(UPPER(TRANSACCIONES!$L$2:$L$1000)="PENDIENTE",ROW(TRANSACCIONES!$L$2:$L$1000)-ROW(TRANSACCIONES!$L$2)+1),28)),"")
A34: =IFERROR(INDEX(TRANSACCIONES!$A$2:$A$1000,SMALL(IF(UPPER(TRANSACCIONES!$L$2:$L$1000)="PENDIENTE",ROW(TRANSACCIONES!$L$2:$L$1000)-ROW(TRANSACCIONES!$L$2)+1),29)),"") | B34: =IFERROR(INDEX(TRANSACCIONES!$E$2:$E$1000,SMALL(IF(UPPER(TRANSACCIONES!$L$2:$L$1000)="PENDIENTE",ROW(TRANSACCIONES!$L$2:$L$1000)-ROW(TRANSACCIONES!$L$2)+1),29)),"") | C34: =IFERROR(INDEX(TRANSACCIONES!$F$2:$F$1000,SMALL(IF(UPPER(TRANSACCIONES!$L$2:$L$1000)="PENDIENTE",ROW(TRANSACCIONES!$L$2:$L$1000)-ROW(TRANSACCIONES!$L$2)+1),29)),"") | D34: =IFERROR(INDEX(TRANSACCIONES!$I$2:$I$1000,SMALL(IF(UPPER(TRANSACCIONES!$L$2:$L$1000)="PENDIENTE",ROW(TRANSACCIONES!$L$2:$L$1000)-ROW(TRANSACCIONES!$L$2)+1),29)),"") | E34: =IFERROR(INDEX(TRANSACCIONES!$N$2:$N$1000,SMALL(IF(UPPER(TRANSACCIONES!$L$2:$L$1000)="PENDIENTE",ROW(TRANSACCIONES!$L$2:$L$1000)-ROW(TRANSACCIONES!$L$2)+1),29)),"") | F34: =IF(A34="","",TODAY()-A34) | G34: =IF(A34="","",IF(E34<TODAY(),"VENCIDO",IF(E34<=TODAY()+7,"POR VENCER","AL DÍA"))) | H34: =IFERROR(INDEX(TRANSACCIONES!$K$2:$K$1000,SMALL(IF(UPPER(TRANSACCIONES!$L$2:$L$1000)="PENDIENTE",ROW(TRANSACCIONES!$L$2:$L$1000)-ROW(TRANSACCIONES!$L$2)+1),29)),"")
A35: =IFERROR(INDEX(TRANSACCIONES!$A$2:$A$1000,SMALL(IF(UPPER(TRANSACCIONES!$L$2:$L$1000)="PENDIENTE",ROW(TRANSACCIONES!$L$2:$L$1000)-ROW(TRANSACCIONES!$L$2)+1),30)),"") | B35: =IFERROR(INDEX(TRANSACCIONES!$E$2:$E$1000,SMALL(IF(UPPER(TRANSACCIONES!$L$2:$L$1000)="PENDIENTE",ROW(TRANSACCIONES!$L$2:$L$1000)-ROW(TRANSACCIONES!$L$2)+1),30)),"") | C35: =IFERROR(INDEX(TRANSACCIONES!$F$2:$F$1000,SMALL(IF(UPPER(TRANSACCIONES!$L$2:$L$1000)="PENDIENTE",ROW(TRANSACCIONES!$L$2:$L$1000)-ROW(TRANSACCIONES!$L$2)+1),30)),"") | D35: =IFERROR(INDEX(TRANSACCIONES!$I$2:$I$1000,SMALL(IF(UPPER(TRANSACCIONES!$L$2:$L$1000)="PENDIENTE",ROW(TRANSACCIONES!$L$2:$L$1000)-ROW(TRANSACCIONES!$L$2)+1),30)),"") | E35: =IFERROR(INDEX(TRANSACCIONES!$N$2:$N$1000,SMALL(IF(UPPER(TRANSACCIONES!$L$2:$L$1000)="PENDIENTE",ROW(TRANSACCIONES!$L$2:$L$1000)-ROW(TRANSACCIONES!$L$2)+1),30)),"") | F35: =IF(A35="","",TODAY()-A35) | G35: =IF(A35="","",IF(E35<TODAY(),"VENCIDO",IF(E35<=TODAY()+7,"POR VENCER","AL DÍA"))) | H35: =IFERROR(INDEX(TRANSACCIONES!$K$2:$K$1000,SMALL(IF(UPPER(TRANSACCIONES!$L$2:$L$1000)="PENDIENTE",ROW(TRANSACCIONES!$L$2:$L$1000)-ROW(TRANSACCIONES!$L$2)+1),30)),"")
A36: =IFERROR(INDEX(TRANSACCIONES!$A$2:$A$1000,SMALL(IF(UPPER(TRANSACCIONES!$L$2:$L$1000)="PENDIENTE",ROW(TRANSACCIONES!$L$2:$L$1000)-ROW(TRANSACCIONES!$L$2)+1),31)),"") | B36: =IFERROR(INDEX(TRANSACCIONES!$E$2:$E$1000,SMALL(IF(UPPER(TRANSACCIONES!$L$2:$L$1000)="PENDIENTE",ROW(TRANSACCIONES!$L$2:$L$1000)-ROW(TRANSACCIONES!$L$2)+1),31)),"") | C36: =IFERROR(INDEX(TRANSACCIONES!$F$2:$F$1000,SMALL(IF(UPPER(TRANSACCIONES!$L$2:$L$1000)="PENDIENTE",ROW(TRANSACCIONES!$L$2:$L$1000)-ROW(TRANSACCIONES!$L$2)+1),31)),"") | D36: =IFERROR(INDEX(TRANSACCIONES!$I$2:$I$1000,SMALL(IF(UPPER(TRANSACCIONES!$L$2:$L$1000)="PENDIENTE",ROW(TRANSACCIONES!$L$2:$L$1000)-ROW(TRANSACCIONES!$L$2)+1),31)),"") | E36: =IFERROR(INDEX(TRANSACCIONES!$N$2:$N$1000,SMALL(IF(UPPER(TRANSACCIONES!$L$2:$L$1000)="PENDIENTE",ROW(TRANSACCIONES!$L$2:$L$1000)-ROW(TRANSACCIONES!$L$2)+1),31)),"") | F36: =IF(A36="","",TODAY()-A36) | G36: =IF(A36="","",IF(E36<TODAY(),"VENCIDO",IF(E36<=TODAY()+7,"POR VENCER","AL DÍA"))) | H36: =IFERROR(INDEX(TRANSACCIONES!$K$2:$K$1000,SMALL(IF(UPPER(TRANSACCIONES!$L$2:$L$1000)="PENDIENTE",ROW(TRANSACCIONES!$L$2:$L$1000)-ROW(TRANSACCIONES!$L$2)+1),31)),"")
A37: =IFERROR(INDEX(TRANSACCIONES!$A$2:$A$1000,SMALL(IF(UPPER(TRANSACCIONES!$L$2:$L$1000)="PENDIENTE",ROW(TRANSACCIONES!$L$2:$L$1000)-ROW(TRANSACCIONES!$L$2)+1),32)),"") | B37: =IFERROR(INDEX(TRANSACCIONES!$E$2:$E$1000,SMALL(IF(UPPER(TRANSACCIONES!$L$2:$L$1000)="PENDIENTE",ROW(TRANSACCIONES!$L$2:$L$1000)-ROW(TRANSACCIONES!$L$2)+1),32)),"") | C37: =IFERROR(INDEX(TRANSACCIONES!$F$2:$F$1000,SMALL(IF(UPPER(TRANSACCIONES!$L$2:$L$1000)="PENDIENTE",ROW(TRANSACCIONES!$L$2:$L$1000)-ROW(TRANSACCIONES!$L$2)+1),32)),"") | D37: =IFERROR(INDEX(TRANSACCIONES!$I$2:$I$1000,SMALL(IF(UPPER(TRANSACCIONES!$L$2:$L$1000)="PENDIENTE",ROW(TRANSACCIONES!$L$2:$L$1000)-ROW(TRANSACCIONES!$L$2)+1),32)),"") | E37: =IFERROR(INDEX(TRANSACCIONES!$N$2:$N$1000,SMALL(IF(UPPER(TRANSACCIONES!$L$2:$L$1000)="PENDIENTE",ROW(TRANSACCIONES!$L$2:$L$1000)-ROW(TRANSACCIONES!$L$2)+1),32)),"") | F37: =IF(A37="","",TODAY()-A37) | G37: =IF(A37="","",IF(E37<TODAY(),"VENCIDO",IF(E37<=TODAY()+7,"POR VENCER","AL DÍA"))) | H37: =IFERROR(INDEX(TRANSACCIONES!$K$2:$K$1000,SMALL(IF(UPPER(TRANSACCIONES!$L$2:$L$1000)="PENDIENTE",ROW(TRANSACCIONES!$L$2:$L$1000)-ROW(TRANSACCIONES!$L$2)+1),32)),"")
A38: =IFERROR(INDEX(TRANSACCIONES!$A$2:$A$1000,SMALL(IF(UPPER(TRANSACCIONES!$L$2:$L$1000)="PENDIENTE",ROW(TRANSACCIONES!$L$2:$L$1000)-ROW(TRANSACCIONES!$L$2)+1),33)),"") | B38: =IFERROR(INDEX(TRANSACCIONES!$E$2:$E$1000,SMALL(IF(UPPER(TRANSACCIONES!$L$2:$L$1000)="PENDIENTE",ROW(TRANSACCIONES!$L$2:$L$1000)-ROW(TRANSACCIONES!$L$2)+1),33)),"") | C38: =IFERROR(INDEX(TRANSACCIONES!$F$2:$F$1000,SMALL(IF(UPPER(TRANSACCIONES!$L$2:$L$1000)="PENDIENTE",ROW(TRANSACCIONES!$L$2:$L$1000)-ROW(TRANSACCIONES!$L$2)+1),33)),"") | D38: =IFERROR(INDEX(TRANSACCIONES!$I$2:$I$1000,SMALL(IF(UPPER(TRANSACCIONES!$L$2:$L$1000)="PENDIENTE",ROW(TRANSACCIONES!$L$2:$L$1000)-ROW(TRANSACCIONES!$L$2)+1),33)),"") | E38: =IFERROR(INDEX(TRANSACCIONES!$N$2:$N$1000,SMALL(IF(UPPER(TRANSACCIONES!$L$2:$L$1000)="PENDIENTE",ROW(TRANSACCIONES!$L$2:$L$1000)-ROW(TRANSACCIONES!$L$2)+1),33)),"") | F38: =IF(A38="","",TODAY()-A38) | G38: =IF(A38="","",IF(E38<TODAY(),"VENCIDO",IF(E38<=TODAY()+7,"POR VENCER","AL DÍA"))) | H38: =IFERROR(INDEX(TRANSACCIONES!$K$2:$K$1000,SMALL(IF(UPPER(TRANSACCIONES!$L$2:$L$1000)="PENDIENTE",ROW(TRANSACCIONES!$L$2:$L$1000)-ROW(TRANSACCIONES!$L$2)+1),33)),"")
A39: =IFERROR(INDEX(TRANSACCIONES!$A$2:$A$1000,SMALL(IF(UPPER(TRANSACCIONES!$L$2:$L$1000)="PENDIENTE",ROW(TRANSACCIONES!$L$2:$L$1000)-ROW(TRANSACCIONES!$L$2)+1),34)),"") | B39: =IFERROR(INDEX(TRANSACCIONES!$E$2:$E$1000,SMALL(IF(UPPER(TRANSACCIONES!$L$2:$L$1000)="PENDIENTE",ROW(TRANSACCIONES!$L$2:$L$1000)-ROW(TRANSACCIONES!$L$2)+1),34)),"") | C39: =IFERROR(INDEX(TRANSACCIONES!$F$2:$F$1000,SMALL(IF(UPPER(TRANSACCIONES!$L$2:$L$1000)="PENDIENTE",ROW(TRANSACCIONES!$L$2:$L$1000)-ROW(TRANSACCIONES!$L$2)+1),34)),"") | D39: =IFERROR(INDEX(TRANSACCIONES!$I$2:$I$1000,SMALL(IF(UPPER(TRANSACCIONES!$L$2:$L$1000)="PENDIENTE",ROW(TRANSACCIONES!$L$2:$L$1000)-ROW(TRANSACCIONES!$L$2)+1),34)),"") | E39: =IFERROR(INDEX(TRANSACCIONES!$N$2:$N$1000,SMALL(IF(UPPER(TRANSACCIONES!$L$2:$L$1000)="PENDIENTE",ROW(TRANSACCIONES!$L$2:$L$1000)-ROW(TRANSACCIONES!$L$2)+1),34)),"") | F39: =IF(A39="","",TODAY()-A39) | G39: =IF(A39="","",IF(E39<TODAY(),"VENCIDO",IF(E39<=TODAY()+7,"POR VENCER","AL DÍA"))) | H39: =IFERROR(INDEX(TRANSACCIONES!$K$2:$K$1000,SMALL(IF(UPPER(TRANSACCIONES!$L$2:$L$1000)="PENDIENTE",ROW(TRANSACCIONES!$L$2:$L$1000)-ROW(TRANSACCIONES!$L$2)+1),34)),"")
A40: =IFERROR(INDEX(TRANSACCIONES!$A$2:$A$1000,SMALL(IF(UPPER(TRANSACCIONES!$L$2:$L$1000)="PENDIENTE",ROW(TRANSACCIONES!$L$2:$L$1000)-ROW(TRANSACCIONES!$L$2)+1),35)),"") | B40: =IFERROR(INDEX(TRANSACCIONES!$E$2:$E$1000,SMALL(IF(UPPER(TRANSACCIONES!$L$2:$L$1000)="PENDIENTE",ROW(TRANSACCIONES!$L$2:$L$1000)-ROW(TRANSACCIONES!$L$2)+1),35)),"") | C40: =IFERROR(INDEX(TRANSACCIONES!$F$2:$F$1000,SMALL(IF(UPPER(TRANSACCIONES!$L$2:$L$1000)="PENDIENTE",ROW(TRANSACCIONES!$L$2:$L$1000)-ROW(TRANSACCIONES!$L$2)+1),35)),"") | D40: =IFERROR(INDEX(TRANSACCIONES!$I$2:$I$1000,SMALL(IF(UPPER(TRANSACCIONES!$L$2:$L$1000)="PENDIENTE",ROW(TRANSACCIONES!$L$2:$L$1000)-ROW(TRANSACCIONES!$L$2)+1),35)),"") | E40: =IFERROR(INDEX(TRANSACCIONES!$N$2:$N$1000,SMALL(IF(UPPER(TRANSACCIONES!$L$2:$L$1000)="PENDIENTE",ROW(TRANSACCIONES!$L$2:$L$1000)-ROW(TRANSACCIONES!$L$2)+1),35)),"") | F40: =IF(A40="","",TODAY()-A40) | G40: =IF(A40="","",IF(E40<TODAY(),"VENCIDO",IF(E40<=TODAY()+7,"POR VENCER","AL DÍA"))) | H40: =IFERROR(INDEX(TRANSACCIONES!$K$2:$K$1000,SMALL(IF(UPPER(TRANSACCIONES!$L$2:$L$1000)="PENDIENTE",ROW(TRANSACCIONES!$L$2:$L$1000)-ROW(TRANSACCIONES!$L$2)+1),35)),"")
A41: =IFERROR(INDEX(TRANSACCIONES!$A$2:$A$1000,SMALL(IF(UPPER(TRANSACCIONES!$L$2:$L$1000)="PENDIENTE",ROW(TRANSACCIONES!$L$2:$L$1000)-ROW(TRANSACCIONES!$L$2)+1),36)),"") | B41: =IFERROR(INDEX(TRANSACCIONES!$E$2:$E$1000,SMALL(IF(UPPER(TRANSACCIONES!$L$2:$L$1000)="PENDIENTE",ROW(TRANSACCIONES!$L$2:$L$1000)-ROW(TRANSACCIONES!$L$2)+1),36)),"") | C41: =IFERROR(INDEX(TRANSACCIONES!$F$2:$F$1000,SMALL(IF(UPPER(TRANSACCIONES!$L$2:$L$1000)="PENDIENTE",ROW(TRANSACCIONES!$L$2:$L$1000)-ROW(TRANSACCIONES!$L$2)+1),36)),"") | D41: =IFERROR(INDEX(TRANSACCIONES!$I$2:$I$1000,SMALL(IF(UPPER(TRANSACCIONES!$L$2:$L$1000)="PENDIENTE",ROW(TRANSACCIONES!$L$2:$L$1000)-ROW(TRANSACCIONES!$L$2)+1),36)),"") | E41: =IFERROR(INDEX(TRANSACCIONES!$N$2:$N$1000,SMALL(IF(UPPER(TRANSACCIONES!$L$2:$L$1000)="PENDIENTE",ROW(TRANSACCIONES!$L$2:$L$1000)-ROW(TRANSACCIONES!$L$2)+1),36)),"") | F41: =IF(A41="","",TODAY()-A41) | G41: =IF(A41="","",IF(E41<TODAY(),"VENCIDO",IF(E41<=TODAY()+7,"POR VENCER","AL DÍA"))) | H41: =IFERROR(INDEX(TRANSACCIONES!$K$2:$K$1000,SMALL(IF(UPPER(TRANSACCIONES!$L$2:$L$1000)="PENDIENTE",ROW(TRANSACCIONES!$L$2:$L$1000)-ROW(TRANSACCIONES!$L$2)+1),36)),"")
A42: =IFERROR(INDEX(TRANSACCIONES!$A$2:$A$1000,SMALL(IF(UPPER(TRANSACCIONES!$L$2:$L$1000)="PENDIENTE",ROW(TRANSACCIONES!$L$2:$L$1000)-ROW(TRANSACCIONES!$L$2)+1),37)),"") | B42: =IFERROR(INDEX(TRANSACCIONES!$E$2:$E$1000,SMALL(IF(UPPER(TRANSACCIONES!$L$2:$L$1000)="PENDIENTE",ROW(TRANSACCIONES!$L$2:$L$1000)-ROW(TRANSACCIONES!$L$2)+1),37)),"") | C42: =IFERROR(INDEX(TRANSACCIONES!$F$2:$F$1000,SMALL(IF(UPPER(TRANSACCIONES!$L$2:$L$1000)="PENDIENTE",ROW(TRANSACCIONES!$L$2:$L$1000)-ROW(TRANSACCIONES!$L$2)+1),37)),"") | D42: =IFERROR(INDEX(TRANSACCIONES!$I$2:$I$1000,SMALL(IF(UPPER(TRANSACCIONES!$L$2:$L$1000)="PENDIENTE",ROW(TRANSACCIONES!$L$2:$L$1000)-ROW(TRANSACCIONES!$L$2)+1),37)),"") | E42: =IFERROR(INDEX(TRANSACCIONES!$N$2:$N$1000,SMALL(IF(UPPER(TRANSACCIONES!$L$2:$L$1000)="PENDIENTE",ROW(TRANSACCIONES!$L$2:$L$1000)-ROW(TRANSACCIONES!$L$2)+1),37)),"") | F42: =IF(A42="","",TODAY()-A42) | G42: =IF(A42="","",IF(E42<TODAY(),"VENCIDO",IF(E42<=TODAY()+7,"POR VENCER","AL DÍA"))) | H42: =IFERROR(INDEX(TRANSACCIONES!$K$2:$K$1000,SMALL(IF(UPPER(TRANSACCIONES!$L$2:$L$1000)="PENDIENTE",ROW(TRANSACCIONES!$L$2:$L$1000)-ROW(TRANSACCIONES!$L$2)+1),37)),"")
...

Sheet CxC
A1: 💵 CUENTAS POR COBRAR
A3: Total por Cobrar: | B3: =SUM(D6:D55)
A5: Fecha | B5: Descripción | C5: Cliente | D5: Monto | E5: Fecha Vencimiento | F5: Días Pendientes | G5: Estado | H5: Notas
A6: =IFERROR(INDEX(TRANSACCIONES!$A$2:$A$1000,SMALL(IF(UPPER(TRANSACCIONES!$L$2:$L$1000)="POR COBRAR",ROW(TRANSACCIONES!$L$2:$L$1000)-ROW(TRANSACCIONES!$L$2)+1),1)),"") | B6: =IFERROR(INDEX(TRANSACCIONES!$E$2:$E$1000,SMALL(IF(UPPER(TRANSACCIONES!$L$2:$L$1000)="POR COBRAR",ROW(TRANSACCIONES!$L$2:$L$1000)-ROW(TRANSACCIONES!$L$2)+1),1)),"") | C6: =IFERROR(INDEX(TRANSACCIONES!$F$2:$F$1000,SMALL(IF(UPPER(TRANSACCIONES!$L$2:$L$1000)="POR COBRAR",ROW(TRANSACCIONES!$L$2:$L$1000)-ROW(TRANSACCIONES!$L$2)+1),1)),"") | D6: =IFERROR(INDEX(TRANSACCIONES!$I$2:$I$1000,SMALL(IF(UPPER(TRANSACCIONES!$L$2:$L$1000)="POR COBRAR",ROW(TRANSACCIONES!$L$2:$L$1000)-ROW(TRANSACCIONES!$L$2)+1),1)),"") | E6: =IFERROR(INDEX(TRANSACCIONES!$N$2:$N$1000,SMALL(IF(UPPER(TRANSACCIONES!$L$2:$L$1000)="POR COBRAR",ROW(TRANSACCIONES!$L$2:$L$1000)-ROW(TRANSACCIONES!$L$2)+1),1)),"") | F6: =IF(A6="","",TODAY()-A6) | G6: =IF(A6="","",IF(E6<TODAY(),"VENCIDO",IF(E6<=TODAY()+7,"POR VENCER","AL DÍA"))) | H6: =IFERROR(INDEX(TRANSACCIONES!$K$2:$K$1000,SMALL(IF(UPPER(TRANSACCIONES!$L$2:$L$1000)="POR COBRAR",ROW(TRANSACCIONES!$L$2:$L$1000)-ROW(TRANSACCIONES!$L$2)+1),1)),"")
A7: =IFERROR(INDEX(TRANSACCIONES!$A$2:$A$1000,SMALL(IF(UPPER(TRANSACCIONES!$L$2:$L$1000)="POR COBRAR",ROW(TRANSACCIONES!$L$2:$L$1000)-ROW(TRANSACCIONES!$L$2)+1),2)),"") | B7: =IFERROR(INDEX(TRANSACCIONES!$E$2:$E$1000,SMALL(IF(UPPER(TRANSACCIONES!$L$2:$L$1000)="POR COBRAR",ROW(TRANSACCIONES!$L$2:$L$1000)-ROW(TRANSACCIONES!$L$2)+1),2)),"") | C7: =IFERROR(INDEX(TRANSACCIONES!$F$2:$F$1000,SMALL(IF(UPPER(TRANSACCIONES!$L$2:$L$1000)="POR COBRAR",ROW(TRANSACCIONES!$L$2:$L$1000)-ROW(TRANSACCIONES!$L$2)+1),2)),"") | D7: =IFERROR(INDEX(TRANSACCIONES!$I$2:$I$1000,SMALL(IF(UPPER(TRANSACCIONES!$L$2:$L$1000)="POR COBRAR",ROW(TRANSACCIONES!$L$2:$L$1000)-ROW(TRANSACCIONES!$L$2)+1),2)),"") | E7: =IFERROR(INDEX(TRANSACCIONES!$N$2:$N$1000,SMALL(IF(UPPER(TRANSACCIONES!$L$2:$L$1000)="POR COBRAR",ROW(TRANSACCIONES!$L$2:$L$1000)-ROW(TRANSACCIONES!$L$2)+1),2)),"") | F7: =IF(A7="","",TODAY()-A7) | G7: =IF(A7="","",IF(E7<TODAY(),"VENCIDO",IF(E7<=TODAY()+7,"POR VENCER","AL DÍA"))) | H7: =IFERROR(INDEX(TRANSACCIONES!$K$2:$K$1000,SMALL(IF(UPPER(TRANSACCIONES!$L$2:$L$1000)="POR COBRAR",ROW(TRANSACCIONES!$L$2:$L$1000)-ROW(TRANSACCIONES!$L$2)+1),2)),"")
A8: =IFERROR(INDEX(TRANSACCIONES!$A$2:$A$1000,SMALL(IF(UPPER(TRANSACCIONES!$L$2:$L$1000)="POR COBRAR",ROW(TRANSACCIONES!$L$2:$L$1000)-ROW(TRANSACCIONES!$L$2)+1),3)),"") | B8: =IFERROR(INDEX(TRANSACCIONES!$E$2:$E$1000,SMALL(IF(UPPER(TRANSACCIONES!$L$2:$L$1000)="POR COBRAR",ROW(TRANSACCIONES!$L$2:$L$1000)-ROW(TRANSACCIONES!$L$2)+1),3)),"") | C8: =IFERROR(INDEX(TRANSACCIONES!$F$2:$F$1000,SMALL(IF(UPPER(TRANSACCIONES!$L$2:$L$1000)="POR COBRAR",ROW(TRANSACCIONES!$L$2:$L$1000)-ROW(TRANSACCIONES!$L$2)+1),3)),"") | D8: =IFERROR(INDEX(TRANSACCIONES!$I$2:$I$1000,SMALL(IF(UPPER(TRANSACCIONES!$L$2:$L$1000)="POR COBRAR",ROW(TRANSACCIONES!$L$2:$L$1000)-ROW(TRANSACCIONES!$L$2)+1),3)),"") | E8: =IFERROR(INDEX(TRANSACCIONES!$N$2:$N$1000,SMALL(IF(UPPER(TRANSACCIONES!$L$2:$L$1000)="POR COBRAR",ROW(TRANSACCIONES!$L$2:$L$1000)-ROW(TRANSACCIONES!$L$2)+1),3)),"") | F8: =IF(A8="","",TODAY()-A8) | G8: =IF(A8="","",IF(E8<TODAY(),"VENCIDO",IF(E8<=TODAY()+7,"POR VENCER","AL DÍA"))) | H8: =IFERROR(INDEX(TRANSACCIONES!$K$2:$K$1000,SMALL(IF(UPPER(TRANSACCIONES!$L$2:$L$1000)="POR COBRAR",ROW(TRANSACCIONES!$L$2:$L$1000)-ROW(TRANSACCIONES!$L$2)+1),3)),"")
A9: =IFERROR(INDEX(TRANSACCIONES!$A$2:$A$1000,SMALL(IF(UPPER(TRANSACCIONES!$L$2:$L$1000)="POR COBRAR",ROW(TRANSACCIONES!$L$2:$L$1000)-ROW(TRANSACCIONES!$L$2)+1),4)),"") | B9: =IFERROR(INDEX(TRANSACCIONES!$E$2:$E$1000,SMALL(IF(UPPER(TRANSACCIONES!$L$2:$L$1000)="POR COBRAR",ROW(TRANSACCIONES!$L$2:$L$1000)-ROW(TRANSACCIONES!$L$2)+1),4)),"") | C9: =IFERROR(INDEX(TRANSACCIONES!$F$2:$F$1000,SMALL(IF(UPPER(TRANSACCIONES!$L$2:$L$1000)="POR COBRAR",ROW(TRANSACCIONES!$L$2:$L$1000)-ROW(TRANSACCIONES!$L$2)+1),4)),"") | D9: =IFERROR(INDEX(TRANSACCIONES!$I$2:$I$1000,SMALL(IF(UPPER(TRANSACCIONES!$L$2:$L$1000)="POR COBRAR",ROW(TRANSACCIONES!$L$2:$L$1000)-ROW(TRANSACCIONES!$L$2)+1),4)),"") | E9: =IFERROR(INDEX(TRANSACCIONES!$N$2:$N$1000,SMALL(IF(UPPER(TRANSACCIONES!$L$2:$L$1000)="POR COBRAR",ROW(TRANSACCIONES!$L$2:$L$1000)-ROW(TRANSACCIONES!$L$2)+1),4)),"") | F9: =IF(A9="","",TODAY()-A9) | G9: =IF(A9="","",IF(E9<TODAY(),"VENCIDO",IF(E9<=TODAY()+7,"POR VENCER","AL DÍA"))) | H9: =IFERROR(INDEX(TRANSACCIONES!$K$2:$K$1000,SMALL(IF(UPPER(TRANSACCIONES!$L$2:$L$1000)="POR COBRAR",ROW(TRANSACCIONES!$L$2:$L$1000)-ROW(TRANSACCIONES!$L$2)+1),4)),"")
A10: =IFERROR(INDEX(TRANSACCIONES!$A$2:$A$1000,SMALL(IF(UPPER(TRANSACCIONES!$L$2:$L$1000)="POR COBRAR",ROW(TRANSACCIONES!$L$2:$L$1000)-ROW(TRANSACCIONES!$L$2)+1),5)),"") | B10: =IFERROR(INDEX(TRANSACCIONES!$E$2:$E$1000,SMALL(IF(UPPER(TRANSACCIONES!$L$2:$L$1000)="POR COBRAR",ROW(TRANSACCIONES!$L$2:$L$1000)-ROW(TRANSACCIONES!$L$2)+1),5)),"") | C10: =IFERROR(INDEX(TRANSACCIONES!$F$2:$F$1000,SMALL(IF(UPPER(TRANSACCIONES!$L$2:$L$1000)="POR COBRAR",ROW(TRANSACCIONES!$L$2:$L$1000)-ROW(TRANSACCIONES!$L$2)+1),5)),"") | D10: =IFERROR(INDEX(TRANSACCIONES!$I$2:$I$1000,SMALL(IF(UPPER(TRANSACCIONES!$L$2:$L$1000)="POR COBRAR",ROW(TRANSACCIONES!$L$2:$L$1000)-ROW(TRANSACCIONES!$L$2)+1),5)),"") | E10: =IFERROR(INDEX(TRANSACCIONES!$N$2:$N$1000,SMALL(IF(UPPER(TRANSACCIONES!$L$2:$L$1000)="POR COBRAR",ROW(TRANSACCIONES!$L$2:$L$1000)-ROW(TRANSACCIONES!$L$2)+1),5)),"") | F10: =IF(A10="","",TODAY()-A10) | G10: =IF(A10="","",IF(E10<TODAY(),"VENCIDO",IF(E10<=TODAY()+7,"POR VENCER","AL DÍA"))) | H10: =IFERROR(INDEX(TRANSACCIONES!$K$2:$K$1000,SMALL(IF(UPPER(TRANSACCIONES!$L$2:$L$1000)="POR COBRAR",ROW(TRANSACCIONES!$L$2:$L$1000)-ROW(TRANSACCIONES!$L$2)+1),5)),"")
A11: =IFERROR(INDEX(TRANSACCIONES!$A$2:$A$1000,SMALL(IF(UPPER(TRANSACCIONES!$L$2:$L$1000)="POR COBRAR",ROW(TRANSACCIONES!$L$2:$L$1000)-ROW(TRANSACCIONES!$L$2)+1),6)),"") | B11: =IFERROR(INDEX(TRANSACCIONES!$E$2:$E$1000,SMALL(IF(UPPER(TRANSACCIONES!$L$2:$L$1000)="POR COBRAR",ROW(TRANSACCIONES!$L$2:$L$1000)-ROW(TRANSACCIONES!$L$2)+1),6)),"") | C11: =IFERROR(INDEX(TRANSACCIONES!$F$2:$F$1000,SMALL(IF(UPPER(TRANSACCIONES!$L$2:$L$1000)="POR COBRAR",ROW(TRANSACCIONES!$L$2:$L$1000)-ROW(TRANSACCIONES!$L$2)+1),6)),"") | D11: =IFERROR(INDEX(TRANSACCIONES!$I$2:$I$1000,SMALL(IF(UPPER(TRANSACCIONES!$L$2:$L$1000)="POR COBRAR",ROW(TRANSACCIONES!$L$2:$L$1000)-ROW(TRANSACCIONES!$L$2)+1),6)),"") | E11: =IFERROR(INDEX(TRANSACCIONES!$N$2:$N$1000,SMALL(IF(UPPER(TRANSACCIONES!$L$2:$L$1000)="POR COBRAR",ROW(TRANSACCIONES!$L$2:$L$1000)-ROW(TRANSACCIONES!$L$2)+1),6)),"") | F11: =IF(A11="","",TODAY()-A11) | G11: =IF(A11="","",IF(E11<TODAY(),"VENCIDO",IF(E11<=TODAY()+7,"POR VENCER","AL DÍA"))) | H11: =IFERROR(INDEX(TRANSACCIONES!$K$2:$K$1000,SMALL(IF(UPPER(TRANSACCIONES!$L$2:$L$1000)="POR COBRAR",ROW(TRANSACCIONES!$L$2:$L$1000)-ROW(TRANSACCIONES!$L$2)+1),6)),"")
A12: =IFERROR(INDEX(TRANSACCIONES!$A$2:$A$1000,SMALL(IF(UPPER(TRANSACCIONES!$L$2:$L$1000)="POR COBRAR",ROW(TRANSACCIONES!$L$2:$L$1000)-ROW(TRANSACCIONES!$L$2)+1),7)),"") | B12: =IFERROR(INDEX(TRANSACCIONES!$E$2:$E$1000,SMALL(IF(UPPER(TRANSACCIONES!$L$2:$L$1000)="POR COBRAR",ROW(TRANSACCIONES!$L$2:$L$1000)-ROW(TRANSACCIONES!$L$2)+1),7)),"") | C12: =IFERROR(INDEX(TRANSACCIONES!$F$2:$F$1000,SMALL(IF(UPPER(TRANSACCIONES!$L$2:$L$1000)="POR COBRAR",ROW(TRANSACCIONES!$L$2:$L$1000)-ROW(TRANSACCIONES!$L$2)+1),7)),"") | D12: =IFERROR(INDEX(TRANSACCIONES!$I$2:$I$1000,SMALL(IF(UPPER(TRANSACCIONES!$L$2:$L$1000)="POR COBRAR",ROW(TRANSACCIONES!$L$2:$L$1000)-ROW(TRANSACCIONES!$L$2)+1),7)),"") | E12: =IFERROR(INDEX(TRANSACCIONES!$N$2:$N$1000,SMALL(IF(UPPER(TRANSACCIONES!$L$2:$L$1000)="POR COBRAR",ROW(TRANSACCIONES!$L$2:$L$1000)-ROW(TRANSACCIONES!$L$2)+1),7)),"") | F12: =IF(A12="","",TODAY()-A12) | G12: =IF(A12="","",IF(E12<TODAY(),"VENCIDO",IF(E12<=TODAY()+7,"POR VENCER","AL DÍA"))) | H12: =IFERROR(INDEX(TRANSACCIONES!$K$2:$K$1000,SMALL(IF(UPPER(TRANSACCIONES!$L$2:$L$1000)="POR COBRAR",ROW(TRANSACCIONES!$L$2:$L$1000)-ROW(TRANSACCIONES!$L$2)+1),7)),"")
A13: =IFERROR(INDEX(TRANSACCIONES!$A$2:$A$1000,SMALL(IF(UPPER(TRANSACCIONES!$L$2:$L$1000)="POR COBRAR",ROW(TRANSACCIONES!$L$2:$L$1000)-ROW(TRANSACCIONES!$L$2)+1),8)),"") | B13: =IFERROR(INDEX(TRANSACCIONES!$E$2:$E$1000,SMALL(IF(UPPER(TRANSACCIONES!$L$2:$L$1000)="POR COBRAR",ROW(TRANSACCIONES!$L$2:$L$1000)-ROW(TRANSACCIONES!$L$2)+1),8)),"") | C13: =IFERROR(INDEX(TRANSACCIONES!$F$2:$F$1000,SMALL(IF(UPPER(TRANSACCIONES!$L$2:$L$1000)="POR COBRAR",ROW(TRANSACCIONES!$L$2:$L$1000)-ROW(TRANSACCIONES!$L$2)+1),8)),"") | D13: =IFERROR(INDEX(TRANSACCIONES!$I$2:$I$1000,SMALL(IF(UPPER(TRANSACCIONES!$L$2:$L$1000)="POR COBRAR",ROW(TRANSACCIONES!$L$2:$L$1000)-ROW(TRANSACCIONES!$L$2)+1),8)),"") | E13: =IFERROR(INDEX(TRANSACCIONES!$N$2:$N$1000,SMALL(IF(UPPER(TRANSACCIONES!$L$2:$L$1000)="POR COBRAR",ROW(TRANSACCIONES!$L$2:$L$1000)-ROW(TRANSACCIONES!$L$2)+1),8)),"") | F13: =IF(A13="","",TODAY()-A13) | G13: =IF(A13="","",IF(E13<TODAY(),"VENCIDO",IF(E13<=TODAY()+7,"POR VENCER","AL DÍA"))) | H13: =IFERROR(INDEX(TRANSACCIONES!$K$2:$K$1000,SMALL(IF(UPPER(TRANSACCIONES!$L$2:$L$1000)="POR COBRAR",ROW(TRANSACCIONES!$L$2:$L$1000)-ROW(TRANSACCIONES!$L$2)+1),8)),"")
A14: =IFERROR(INDEX(TRANSACCIONES!$A$2:$A$1000,SMALL(IF(UPPER(TRANSACCIONES!$L$2:$L$1000)="POR COBRAR",ROW(TRANSACCIONES!$L$2:$L$1000)-ROW(TRANSACCIONES!$L$2)+1),9)),"") | B14: =IFERROR(INDEX(TRANSACCIONES!$E$2:$E$1000,SMALL(IF(UPPER(TRANSACCIONES!$L$2:$L$1000)="POR COBRAR",ROW(TRANSACCIONES!$L$2:$L$1000)-ROW(TRANSACCIONES!$L$2)+1),9)),"") | C14: =IFERROR(INDEX(TRANSACCIONES!$F$2:$F$1000,SMALL(IF(UPPER(TRANSACCIONES!$L$2:$L$1000)="POR COBRAR",ROW(TRANSACCIONES!$L$2:$L$1000)-ROW(TRANSACCIONES!$L$2)+1),9)),"") | D14: =IFERROR(INDEX(TRANSACCIONES!$I$2:$I$1000,SMALL(IF(UPPER(TRANSACCIONES!$L$2:$L$1000)="POR COBRAR",ROW(TRANSACCIONES!$L$2:$L$1000)-ROW(TRANSACCIONES!$L$2)+1),9)),"") | E14: =IFERROR(INDEX(TRANSACCIONES!$N$2:$N$1000,SMALL(IF(UPPER(TRANSACCIONES!$L$2:$L$1000)="POR COBRAR",ROW(TRANSACCIONES!$L$2:$L$1000)-ROW(TRANSACCIONES!$L$2)+1),9)),"") | F14: =IF(A14="","",TODAY()-A14) | G14: =IF(A14="","",IF(E14<TODAY(),"VENCIDO",IF(E14<=TODAY()+7,"POR VENCER","AL DÍA"))) | H14: =IFERROR(INDEX(TRANSACCIONES!$K$2:$K$1000,SMALL(IF(UPPER(TRANSACCIONES!$L$2:$L$1000)="POR COBRAR",ROW(TRANSACCIONES!$L$2:$L$1000)-ROW(TRANSACCIONES!$L$2)+1),9)),"")
A15: =IFERROR(INDEX(TRANSACCIONES!$A$2:$A$1000,SMALL(IF(UPPER(TRANSACCIONES!$L$2:$L$1000)="POR COBRAR",ROW(TRANSACCIONES!$L$2:$L$1000)-ROW(TRANSACCIONES!$L$2)+1),10)),"") | B15: =IFERROR(INDEX(TRANSACCIONES!$E$2:$E$1000,SMALL(IF(UPPER(TRANSACCIONES!$L$2:$L$1000)="POR COBRAR",ROW(TRANSACCIONES!$L$2:$L$1000)-ROW(TRANSACCIONES!$L$2)+1),10)),"") | C15: =IFERROR(INDEX(TRANSACCIONES!$F$2:$F$1000,SMALL(IF(UPPER(TRANSACCIONES!$L$2:$L$1000)="POR COBRAR",ROW(TRANSACCIONES!$L$2:$L$1000)-ROW(TRANSACCIONES!$L$2)+1),10)),"") | D15: =IFERROR(INDEX(TRANSACCIONES!$I$2:$I$1000,SMALL(IF(UPPER(TRANSACCIONES!$L$2:$L$1000)="POR COBRAR",ROW(TRANSACCIONES!$L$2:$L$1000)-ROW(TRANSACCIONES!$L$2)+1),10)),"") | E15: =IFERROR(INDEX(TRANSACCIONES!$N$2:$N$1000,SMALL(IF(UPPER(TRANSACCIONES!$L$2:$L$1000)="POR COBRAR",ROW(TRANSACCIONES!$L$2:$L$1000)-ROW(TRANSACCIONES!$L$2)+1),10)),"") | F15: =IF(A15="","",TODAY()-A15) | G15: =IF(A15="","",IF(E15<TODAY(),"VENCIDO",IF(E15<=TODAY()+7,"POR VENCER","AL DÍA"))) | H15: =IFERROR(INDEX(TRANSACCIONES!$K$2:$K$1000,SMALL(IF(UPPER(TRANSACCIONES!$L$2:$L$1000)="POR COBRAR",ROW(TRANSACCIONES!$L$2:$L$1000)-ROW(TRANSACCIONES!$L$2)+1),10)),"")
A16: =IFERROR(INDEX(TRANSACCIONES!$A$2:$A$1000,SMALL(IF(UPPER(TRANSACCIONES!$L$2:$L$1000)="POR COBRAR",ROW(TRANSACCIONES!$L$2:$L$1000)-ROW(TRANSACCIONES!$L$2)+1),11)),"") | B16: =IFERROR(INDEX(TRANSACCIONES!$E$2:$E$1000,SMALL(IF(UPPER(TRANSACCIONES!$L$2:$L$1000)="POR COBRAR",ROW(TRANSACCIONES!$L$2:$L$1000)-ROW(TRANSACCIONES!$L$2)+1),11)),"") | C16: =IFERROR(INDEX(TRANSACCIONES!$F$2:$F$1000,SMALL(IF(UPPER(TRANSACCIONES!$L$2:$L$1000)="POR COBRAR",ROW(TRANSACCIONES!$L$2:$L$1000)-ROW(TRANSACCIONES!$L$2)+1),11)),"") | D16: =IFERROR(INDEX(TRANSACCIONES!$I$2:$I$1000,SMALL(IF(UPPER(TRANSACCIONES!$L$2:$L$1000)="POR COBRAR",ROW(TRANSACCIONES!$L$2:$L$1000)-ROW(TRANSACCIONES!$L$2)+1),11)),"") | E16: =IFERROR(INDEX(TRANSACCIONES!$N$2:$N$1000,SMALL(IF(UPPER(TRANSACCIONES!$L$2:$L$1000)="POR COBRAR",ROW(TRANSACCIONES!$L$2:$L$1000)-ROW(TRANSACCIONES!$L$2)+1),11)),"") | F16: =IF(A16="","",TODAY()-A16) | G16: =IF(A16="","",IF(E16<TODAY(),"VENCIDO",IF(E16<=TODAY()+7,"POR VENCER","AL DÍA"))) | H16: =IFERROR(INDEX(TRANSACCIONES!$K$2:$K$1000,SMALL(IF(UPPER(TRANSACCIONES!$L$2:$L$1000)="POR COBRAR",ROW(TRANSACCIONES!$L$2:$L$1000)-ROW(TRANSACCIONES!$L$2)+1),11)),"")
A17: =IFERROR(INDEX(TRANSACCIONES!$A$2:$A$1000,SMALL(IF(UPPER(TRANSACCIONES!$L$2:$L$1000)="POR COBRAR",ROW(TRANSACCIONES!$L$2:$L$1000)-ROW(TRANSACCIONES!$L$2)+1),12)),"") | B17: =IFERROR(INDEX(TRANSACCIONES!$E$2:$E$1000,SMALL(IF(UPPER(TRANSACCIONES!$L$2:$L$1000)="POR COBRAR",ROW(TRANSACCIONES!$L$2:$L$1000)-ROW(TRANSACCIONES!$L$2)+1),12)),"") | C17: =IFERROR(INDEX(TRANSACCIONES!$F$2:$F$1000,SMALL(IF(UPPER(TRANSACCIONES!$L$2:$L$1000)="POR COBRAR",ROW(TRANSACCIONES!$L$2:$L$1000)-ROW(TRANSACCIONES!$L$2)+1),12)),"") | D17: =IFERROR(INDEX(TRANSACCIONES!$I$2:$I$1000,SMALL(IF(UPPER(TRANSACCIONES!$L$2:$L$1000)="POR COBRAR",ROW(TRANSACCIONES!$L$2:$L$1000)-ROW(TRANSACCIONES!$L$2)+1),12)),"") | E17: =IFERROR(INDEX(TRANSACCIONES!$N$2:$N$1000,SMALL(IF(UPPER(TRANSACCIONES!$L$2:$L$1000)="POR COBRAR",ROW(TRANSACCIONES!$L$2:$L$1000)-ROW(TRANSACCIONES!$L$2)+1),12)),"") | F17: =IF(A17="","",TODAY()-A17) | G17: =IF(A17="","",IF(E17<TODAY(),"VENCIDO",IF(E17<=TODAY()+7,"POR VENCER","AL DÍA"))) | H17: =IFERROR(INDEX(TRANSACCIONES!$K$2:$K$1000,SMALL(IF(UPPER(TRANSACCIONES!$L$2:$L$1000)="POR COBRAR",ROW(TRANSACCIONES!$L$2:$L$1000)-ROW(TRANSACCIONES!$L$2)+1),12)),"")
A18: =IFERROR(INDEX(TRANSACCIONES!$A$2:$A$1000,SMALL(IF(UPPER(TRANSACCIONES!$L$2:$L$1000)="POR COBRAR",ROW(TRANSACCIONES!$L$2:$L$1000)-ROW(TRANSACCIONES!$L$2)+1),13)),"") | B18: =IFERROR(INDEX(TRANSACCIONES!$E$2:$E$1000,SMALL(IF(UPPER(TRANSACCIONES!$L$2:$L$1000)="POR COBRAR",ROW(TRANSACCIONES!$L$2:$L$1000)-ROW(TRANSACCIONES!$L$2)+1),13)),"") | C18: =IFERROR(INDEX(TRANSACCIONES!$F$2:$F$1000,SMALL(IF(UPPER(TRANSACCIONES!$L$2:$L$1000)="POR COBRAR",ROW(TRANSACCIONES!$L$2:$L$1000)-ROW(TRANSACCIONES!$L$2)+1),13)),"") | D18: =IFERROR(INDEX(TRANSACCIONES!$I$2:$I$1000,SMALL(IF(UPPER(TRANSACCIONES!$L$2:$L$1000)="POR COBRAR",ROW(TRANSACCIONES!$L$2:$L$1000)-ROW(TRANSACCIONES!$L$2)+1),13)),"") | E18: =IFERROR(INDEX(TRANSACCIONES!$N$2:$N$1000,SMALL(IF(UPPER(TRANSACCIONES!$L$2:$L$1000)="POR COBRAR",ROW(TRANSACCIONES!$L$2:$L$1000)-ROW(TRANSACCIONES!$L$2)+1),13)),"") | F18: =IF(A18="","",TODAY()-A18) | G18: =IF(A18="","",IF(E18<TODAY(),"VENCIDO",IF(E18<=TODAY()+7,"POR VENCER","AL DÍA"))) | H18: =IFERROR(INDEX(TRANSACCIONES!$K$2:$K$1000,SMALL(IF(UPPER(TRANSACCIONES!$L$2:$L$1000)="POR COBRAR",ROW(TRANSACCIONES!$L$2:$L$1000)-ROW(TRANSACCIONES!$L$2)+1),13)),"")
