Workbook

Sheet RESUMEN
A1: DASHBOARD FINANCIERO - AlvaroVelasco Net SRL
A2: Última actualización: 17/11/2025 00:00
A4: CUENTAS POR PAGAR (CxP)
A5: Total CxP USD: | B5: =SUMIF(CxP!D3:D1000,"USD",CxP!H3:H1000)
A6: Total CxP CRC: | B6: =SUMIF(CxP!D3:D1000,"CRC",CxP!C3:C1000)
A7: Facturas vencidas: | B7: =COUNTIF(CxP!G3:G1000,">0")
A8: Promedio días pago: | B8: =AVERAGE(CxP!G3:G1000)
A10: CUENTAS POR COBRAR (CxC)
A11: Total CxC USD: | B11: =SUMIF(CxC!D3:D1000,"USD",CxC!H3:H1000)
A12: Total CxC CRC: | B12: =SUMIF(CxC!D3:D1000,"CRC",CxC!C3:C1000)
A13: Facturas >60 días: | B13: =COUNTIF(CxC!G3:G1000,">60")
A14: Promedio días cobro: | B14: =AVERAGE(CxC!G3:G1000)
A15: % CxC en riesgo (>90): | B15: =IFERROR(SUMIF(CxC!G3:G1000,">90",CxC!H3:H1000)/SUM(CxC!H3:H1000)*100,0)
A17: RATIOS FINANCIEROS
A18: Activo Corriente: | B18: =BALANCE_GENERAL!B8
A19: Pasivo Corriente: | B19: =BALANCE_GENERAL!B22
A20: Ratio Liquidez: | B20: =IFERROR(B18/B19,0)
A21: Capital de Trabajo: | B21: =B18-B19
A22: Quick Ratio: | B22: =IFERROR((BALANCE_GENERAL!B5+BALANCE_GENERAL!B6)/BALANCE_GENERAL!B22,0)
A24: FLUJO DE CAJA
A25: Ingresos mes USD: | B25: =SUMIFS(TRANSACCIONES!F:F,TRANSACCIONES!C:C,"Ingreso",TRANSACCIONES!E:E,"USD")
A26: Gastos mes USD: | B26: =SUMIFS(TRANSACCIONES!F:F,TRANSACCIONES!C:C,"Gasto",TRANSACCIONES!E:E,"USD")
A27: Balance mes USD: | B27: =B25-B26
A28: Efectivo disponible: | B28: =BALANCE_GENERAL!B5
A30: EFICIENCIA OPERACIONAL
A31: Días promedio CxC: | B31: =IFERROR(AVERAGE(CxC!G3:G1000),0)
A32: Días promedio CxP: | B32: =IFERROR(AVERAGE(CxP!G3:G1000),0)
A33: Ciclo conversión $ (días): | B33: =B31-B32
A34: Burn Rate (mes): | B34: =SUMIFS(TRANSACCIONES!F:F,TRANSACCIONES!C:C,"Gasto",TRANSACCIONES!E:E,"USD")/1
A35: Runway (meses): | B35: =IFERROR(B31/B34,0)
A37: RENTABILIDAD
A38: Ingresos totales: | B38: =ESTADO_RESULTADOS!B8
A39: Utilidad bruta: | B39: =ESTADO_RESULTADOS!B15
A40: Margen bruto %: | B40: =ESTADO_RESULTADOS!B16
A41: Utilidad neta: | B41: =ESTADO_RESULTADOS!B40
A42: Margen neto %: | B42: =ESTADO_RESULTADOS!B41
A43: ROE %: | B43: =IFERROR(ESTADO_RESULTADOS!B40/BALANCE_GENERAL!B34*100,0)
A45: IVA CONTROL
A46: IVA Ventas: | B46: =SUMIFS(IVA_CONTROL!D:D,IVA_CONTROL!E:E,"Venta")
A47: IVA Compras: | B47: =SUMIFS(IVA_CONTROL!D:D,IVA_CONTROL!E:E,"Compra")
...

Sheet TRANSACCIONES
A1: TRANSACCIONES - ÚNICA FUENTE DE VERDAD
A2: Fecha | B2: Entidad | C2: Categoría | D2: Subcategoría | E2: Moneda | F2: Monto | G2: Descripción | H2: Forma Pago | I2: IVA | J2: Notas | K2: Recurrente | L2: Proyecto | M2: Estado | N2: Factura # | O2: Tag | P2: Personal/Negocio | Q2: TC Aplicado | R2: ✓ Validación | S2: Días Trans | T2: Equiv USD | U2: Fecha Venc | V2: Prior CxP | W2: Prior CxC
A3: 45978 | B3: BAC San José | C3: CxP | D3: Tarjeta Crédito | E3: CRC | F3: 1831000 | G3: Saldo tarjeta Visa Clásica | H3: Tarjeta Crédito | I3: No | J3: Pre-cargado - Corte día 15 | K3: No | M3: Pendiente | O3: Deuda Inicial | P3: Negocio | Q3: 1 | R3: =IF(AND(A3<>"",ISNUMBER(A3),B3<>"",C3<>"",OR(E3="USD",E3="CRC"),F3>0,ISNUMBER(Q3),Q3>0),"✓ OK","✗ ERROR: Revisa datos") | S3: 0 | T3: 3390.7407 | U3: 46008 | V3: Baja
A4: 45978 | B4: BCR | C4: CxP | D4: Tarjeta Crédito | E4: CRC | F4: 1750000 | G4: Saldo tarjeta Mastercard | H4: Tarjeta Crédito | I4: No | J4: Pre-cargado - Corte día 20 | K4: No | M4: Pendiente | O4: Deuda Inicial | P4: Negocio | Q4: 1 | R4: =IF(AND(A4<>"",ISNUMBER(A4),B4<>"",C4<>"",OR(E4="USD",E4="CRC"),F4>0,ISNUMBER(Q4),Q4>0),"✓ OK","✗ ERROR: Revisa datos") | S4: 0 | T4: 3240.7407 | U4: 46008 | V4: Baja
A5: 45978 | B5: Credomatic | C5: CxP | D5: Tarjeta Crédito | E5: USD | F5: 2500 | G5: Saldo tarjeta Platinum | H5: Tarjeta Crédito | I5: No | J5: Pre-cargado - Corte día 10 | K5: No | M5: Pendiente | O5: Deuda Inicial | P5: Negocio | Q5: 540 | R5: =IF(AND(A5<>"",ISNUMBER(A5),B5<>"",C5<>"",OR(E5="USD",E5="CRC"),F5>0,ISNUMBER(Q5),Q5>0),"✓ OK","✗ ERROR: Revisa datos") | S5: 0 | T5: 2500 | U5: 46008 | V5: Baja
A6: 45978 | B6: Credomatic | C6: CxP | D6: Tarjeta Crédito | E6: CRC | F6: 2800000 | G6: Saldo tarjeta Gold | H6: Tarjeta Crédito | I6: No | J6: Pre-cargado - Corte día 10 | K6: No | M6: Pendiente | O6: Deuda Inicial | P6: Negocio | Q6: 1 | R6: =IF(AND(A6<>"",ISNUMBER(A6),B6<>"",C6<>"",OR(E6="USD",E6="CRC"),F6>0,ISNUMBER(Q6),Q6>0),"✓ OK","✗ ERROR: Revisa datos") | S6: 0 | T6: 5185.1852 | U6: 46008 | V6: Baja
Q7: =IF(E7="USD",CONFIG!$B$5,1) | R7: =IF(AND(A7<>"",ISNUMBER(A7),B7<>"",C7<>"",OR(E7="USD",E7="CRC"),F7>0,ISNUMBER(Q7),Q7>0),"✓ OK","✗ ERROR: Revisa datos") | S7: =IF(A7<>"",TODAY()-A7,"") | T7: =IF(E7="USD",F7,IF(E7="CRC",F7/CONFIG!$B$5,"")) | U7: =IF(A7<>"",A7+30,"") | V7: =IF(AND(C7="CxP",S7>60),"Alta",IF(AND(C7="CxP",S7>30),"Media",IF(C7="CxP","Baja",""))) | W7: =IF(AND(C7="CxC",S7>90),"Alta",IF(AND(C7="CxC",S7>60),"Media",IF(C7="CxC","Baja","")))
Q8: =IF(E8="USD",CONFIG!$B$5,1) | R8: =IF(AND(A8<>"",ISNUMBER(A8),B8<>"",C8<>"",OR(E8="USD",E8="CRC"),F8>0,ISNUMBER(Q8),Q8>0),"✓ OK","✗ ERROR: Revisa datos") | S8: =IF(A8<>"",TODAY()-A8,"") | T8: =IF(E8="USD",F8,IF(E8="CRC",F8/CONFIG!$B$5,"")) | U8: =IF(A8<>"",A8+30,"") | V8: =IF(AND(C8="CxP",S8>60),"Alta",IF(AND(C8="CxP",S8>30),"Media",IF(C8="CxP","Baja",""))) | W8: =IF(AND(C8="CxC",S8>90),"Alta",IF(AND(C8="CxC",S8>60),"Media",IF(C8="CxC","Baja","")))
Q9: =IF(E9="USD",CONFIG!$B$5,1) | R9: =IF(AND(A9<>"",ISNUMBER(A9),B9<>"",C9<>"",OR(E9="USD",E9="CRC"),F9>0,ISNUMBER(Q9),Q9>0),"✓ OK","✗ ERROR: Revisa datos") | S9: =IF(A9<>"",TODAY()-A9,"") | T9: =IF(E9="USD",F9,IF(E9="CRC",F9/CONFIG!$B$5,"")) | U9: =IF(A9<>"",A9+30,"") | V9: =IF(AND(C9="CxP",S9>60),"Alta",IF(AND(C9="CxP",S9>30),"Media",IF(C9="CxP","Baja",""))) | W9: =IF(AND(C9="CxC",S9>90),"Alta",IF(AND(C9="CxC",S9>60),"Media",IF(C9="CxC","Baja","")))
Q10: =IF(E10="USD",CONFIG!$B$5,1) | R10: =IF(AND(A10<>"",ISNUMBER(A10),B10<>"",C10<>"",OR(E10="USD",E10="CRC"),F10>0,ISNUMBER(Q10),Q10>0),"✓ OK","✗ ERROR: Revisa datos") | S10: =IF(A10<>"",TODAY()-A10,"") | T10: =IF(E10="USD",F10,IF(E10="CRC",F10/CONFIG!$B$5,"")) | U10: =IF(A10<>"",A10+30,"") | V10: =IF(AND(C10="CxP",S10>60),"Alta",IF(AND(C10="CxP",S10>30),"Media",IF(C10="CxP","Baja",""))) | W10: =IF(AND(C10="CxC",S10>90),"Alta",IF(AND(C10="CxC",S10>60),"Media",IF(C10="CxC","Baja","")))
Q11: =IF(E11="USD",CONFIG!$B$5,1) | R11: =IF(AND(A11<>"",ISNUMBER(A11),B11<>"",C11<>"",OR(E11="USD",E11="CRC"),F11>0,ISNUMBER(Q11),Q11>0),"✓ OK","✗ ERROR: Revisa datos") | S11: =IF(A11<>"",TODAY()-A11,"") | T11: =IF(E11="USD",F11,IF(E11="CRC",F11/CONFIG!$B$5,"")) | U11: =IF(A11<>"",A11+30,"") | V11: =IF(AND(C11="CxP",S11>60),"Alta",IF(AND(C11="CxP",S11>30),"Media",IF(C11="CxP","Baja",""))) | W11: =IF(AND(C11="CxC",S11>90),"Alta",IF(AND(C11="CxC",S11>60),"Media",IF(C11="CxC","Baja","")))
Q12: =IF(E12="USD",CONFIG!$B$5,1) | R12: =IF(AND(A12<>"",ISNUMBER(A12),B12<>"",C12<>"",OR(E12="USD",E12="CRC"),F12>0,ISNUMBER(Q12),Q12>0),"✓ OK","✗ ERROR: Revisa datos") | S12: =IF(A12<>"",TODAY()-A12,"") | T12: =IF(E12="USD",F12,IF(E12="CRC",F12/CONFIG!$B$5,"")) | U12: =IF(A12<>"",A12+30,"") | V12: =IF(AND(C12="CxP",S12>60),"Alta",IF(AND(C12="CxP",S12>30),"Media",IF(C12="CxP","Baja",""))) | W12: =IF(AND(C12="CxC",S12>90),"Alta",IF(AND(C12="CxC",S12>60),"Media",IF(C12="CxC","Baja","")))
Q13: =IF(E13="USD",CONFIG!$B$5,1) | R13: =IF(AND(A13<>"",ISNUMBER(A13),B13<>"",C13<>"",OR(E13="USD",E13="CRC"),F13>0,ISNUMBER(Q13),Q13>0),"✓ OK","✗ ERROR: Revisa datos") | S13: =IF(A13<>"",TODAY()-A13,"") | T13: =IF(E13="USD",F13,IF(E13="CRC",F13/CONFIG!$B$5,"")) | U13: =IF(A13<>"",A13+30,"") | V13: =IF(AND(C13="CxP",S13>60),"Alta",IF(AND(C13="CxP",S13>30),"Media",IF(C13="CxP","Baja",""))) | W13: =IF(AND(C13="CxC",S13>90),"Alta",IF(AND(C13="CxC",S13>60),"Media",IF(C13="CxC","Baja","")))
Q14: =IF(E14="USD",CONFIG!$B$5,1) | R14: =IF(AND(A14<>"",ISNUMBER(A14),B14<>"",C14<>"",OR(E14="USD",E14="CRC"),F14>0,ISNUMBER(Q14),Q14>0),"✓ OK","✗ ERROR: Revisa datos") | S14: =IF(A14<>"",TODAY()-A14,"") | T14: =IF(E14="USD",F14,IF(E14="CRC",F14/CONFIG!$B$5,"")) | U14: =IF(A14<>"",A14+30,"") | V14: =IF(AND(C14="CxP",S14>60),"Alta",IF(AND(C14="CxP",S14>30),"Media",IF(C14="CxP","Baja",""))) | W14: =IF(AND(C14="CxC",S14>90),"Alta",IF(AND(C14="CxC",S14>60),"Media",IF(C14="CxC","Baja","")))
Q15: =IF(E15="USD",CONFIG!$B$5,1) | R15: =IF(AND(A15<>"",ISNUMBER(A15),B15<>"",C15<>"",OR(E15="USD",E15="CRC"),F15>0,ISNUMBER(Q15),Q15>0),"✓ OK","✗ ERROR: Revisa datos") | S15: =IF(A15<>"",TODAY()-A15,"") | T15: =IF(E15="USD",F15,IF(E15="CRC",F15/CONFIG!$B$5,"")) | U15: =IF(A15<>"",A15+30,"") | V15: =IF(AND(C15="CxP",S15>60),"Alta",IF(AND(C15="CxP",S15>30),"Media",IF(C15="CxP","Baja",""))) | W15: =IF(AND(C15="CxC",S15>90),"Alta",IF(AND(C15="CxC",S15>60),"Media",IF(C15="CxC","Baja","")))
Q16: =IF(E16="USD",CONFIG!$B$5,1) | R16: =IF(AND(A16<>"",ISNUMBER(A16),B16<>"",C16<>"",OR(E16="USD",E16="CRC"),F16>0,ISNUMBER(Q16),Q16>0),"✓ OK","✗ ERROR: Revisa datos") | S16: =IF(A16<>"",TODAY()-A16,"") | T16: =IF(E16="USD",F16,IF(E16="CRC",F16/CONFIG!$B$5,"")) | U16: =IF(A16<>"",A16+30,"") | V16: =IF(AND(C16="CxP",S16>60),"Alta",IF(AND(C16="CxP",S16>30),"Media",IF(C16="CxP","Baja",""))) | W16: =IF(AND(C16="CxC",S16>90),"Alta",IF(AND(C16="CxC",S16>60),"Media",IF(C16="CxC","Baja","")))
Q17: =IF(E17="USD",CONFIG!$B$5,1) | R17: =IF(AND(A17<>"",ISNUMBER(A17),B17<>"",C17<>"",OR(E17="USD",E17="CRC"),F17>0,ISNUMBER(Q17),Q17>0),"✓ OK","✗ ERROR: Revisa datos") | S17: =IF(A17<>"",TODAY()-A17,"") | T17: =IF(E17="USD",F17,IF(E17="CRC",F17/CONFIG!$B$5,"")) | U17: =IF(A17<>"",A17+30,"") | V17: =IF(AND(C17="CxP",S17>60),"Alta",IF(AND(C17="CxP",S17>30),"Media",IF(C17="CxP","Baja",""))) | W17: =IF(AND(C17="CxC",S17>90),"Alta",IF(AND(C17="CxC",S17>60),"Media",IF(C17="CxC","Baja","")))
Q18: =IF(E18="USD",CONFIG!$B$5,1) | R18: =IF(AND(A18<>"",ISNUMBER(A18),B18<>"",C18<>"",OR(E18="USD",E18="CRC"),F18>0,ISNUMBER(Q18),Q18>0),"✓ OK","✗ ERROR: Revisa datos") | S18: =IF(A18<>"",TODAY()-A18,"") | T18: =IF(E18="USD",F18,IF(E18="CRC",F18/CONFIG!$B$5,"")) | U18: =IF(A18<>"",A18+30,"") | V18: =IF(AND(C18="CxP",S18>60),"Alta",IF(AND(C18="CxP",S18>30),"Media",IF(C18="CxP","Baja",""))) | W18: =IF(AND(C18="CxC",S18>90),"Alta",IF(AND(C18="CxC",S18>60),"Media",IF(C18="CxC","Baja","")))
... Q1000: =IF(E1000="USD",CONFIG!$B$5,1) | R1000: =IF(AND(A1000<>"",ISNUMBER(A1000),B1000<>"",C1000<>"",OR(E1000="USD",E1000="CRC"),F1000>0,ISNUMBER(Q1000),Q1000>0),"✓ OK","✗ ERROR: Revisa datos") | S1000: =IF(A1000<>"",TODAY()-A1000,"") | T1000: =IF(E1000="USD",F1000,IF(E1000="CRC",F1000/CONFIG!$B$5,"")) | U1000: =IF(A1000<>"",A1000+30,"") | V1000: =IF(AND(C1000="CxP",S1000>60),"Alta",IF(AND(C1000="CxP",S1000>30),"Media",IF(C1000="CxP","Baja",""))) | W1000: =IF(AND(C1000="CxC",S1000>90),"Alta",IF(AND(C1000="CxC",S1000>60),"Media",IF(C1000="CxC","Baja","")))

Sheet CONFIG
A1: CONFIGURACIÓN DEL SISTEMA
A2: ⚠️ Celdas amarillas son EDITABLES - No modificar fórmulas
A4: Parámetro | B4: Valor | C4: Descripción
A5: Tipo Cambio USD→CRC | B5: 540 | C5: Tipo de cambio actual
A6: BAC Visa - Día Corte | B6: 15 | C6: Día de corte mensual
A7: BCR Mastercard - Día Corte | B7: 20 | C7: Día de corte mensual
A8: Credomatic Platinum - Día Corte | B8: 10 | C8: Día de corte mensual
A9: Credomatic Gold - Día Corte | B9: 10 | C9: Día de corte mensual
A10: Proveedor Zona Franca 1 | B10: VWR International LLC | C10: Exento de IVA
A11: Proveedor Zona Franca 2 | B11: RS Hughes Co. Inc. | C11: Exento de IVA
A12: IVA Costa Rica % | B12: 13 | C12: Porcentaje IVA estándar
A13: Mes Actual de Trabajo | B13: Noviembre 2025 | C13: Cambiar al hacer cierre
A14: Último Cierre Realizado | B14: 31/10/2025 | C14: Auto-actualiza

Sheet CxP
A1: CUENTAS POR PAGAR (CxP)
A2: Entidad | B2: Fecha | C2: Monto | D2: Moneda | E2: Descripción | F2: Estado | G2: Días Vencidos | H2: Equiv USD | I2: Factura # | J2: Fecha Venc | K2: Prioridad | L2: Contacto
A3: =FILTER(TRANSACCIONES!B3:B1000;(TRANSACCIONES!C3:C1000="CxP")*(TRANSACCIONES!M3:M1000="Pendiente");"Sin CxP pendientes") | B3: =FILTER(TRANSACCIONES!A3:A1000;(TRANSACCIONES!C3:C1000="CxP")*(TRANSACCIONES!M3:M1000="Pendiente");"") | C3: =FILTER(TRANSACCIONES!F3:F1000;(TRANSACCIONES!C3:C1000="CxP")*(TRANSACCIONES!M3:M1000="Pendiente");"") | D3: =FILTER(TRANSACCIONES!E3:E1000;(TRANSACCIONES!C3:C1000="CxP")*(TRANSACCIONES!M3:M1000="Pendiente");"") | E3: =FILTER(TRANSACCIONES!G3:G1000;(TRANSACCIONES!C3:C1000="CxP")*(TRANSACCIONES!M3:M1000="Pendiente");"") | F3: =FILTER(TRANSACCIONES!M3:M1000;(TRANSACCIONES!C3:C1000="CxP")*(TRANSACCIONES!M3:M1000="Pendiente");"") | G3: =FILTER(TRANSACCIONES!S3:S1000;(TRANSACCIONES!C3:C1000="CxP")*(TRANSACCIONES!M3:M1000="Pendiente");"") | H3: =FILTER(TRANSACCIONES!T3:T1000;(TRANSACCIONES!C3:C1000="CxP")*(TRANSACCIONES!M3:M1000="Pendiente");"") | I3: =FILTER(TRANSACCIONES!N3:N1000;(TRANSACCIONES!C3:C1000="CxP")*(TRANSACCIONES!M3:M1000="Pendiente");"") | J3: =FILTER(TRANSACCIONES!U3:U1000;(TRANSACCIONES!C3:C1000="CxP")*(TRANSACCIONES!M3:M1000="Pendiente");"") | K3: =FILTER(TRANSACCIONES!V3:V1000;(TRANSACCIONES!C3:C1000="CxP")*(TRANSACCIONES!M3:M1000="Pendiente");"")

Sheet CxC
A1: CUENTAS POR COBRAR (CxC)
A2: Entidad | B2: Fecha | C2: Monto | D2: Moneda | E2: Descripción | F2: Estado | G2: Días Pendientes | H2: Equiv USD | I2: Factura # | J2: Fecha Venc | K2: Prioridad | L2: Contacto
A3: =FILTER(TRANSACCIONES!B3:B1000;(TRANSACCIONES!C3:C1000="CxC")*(TRANSACCIONES!M3:M1000="Pendiente");"Sin CxC pendientes") | B3: =FILTER(TRANSACCIONES!A3:A1000;(TRANSACCIONES!C3:C1000="CxC")*(TRANSACCIONES!M3:M1000="Pendiente");"") | C3: =FILTER(TRANSACCIONES!F3:F1000;(TRANSACCIONES!C3:C1000="CxC")*(TRANSACCIONES!M3:M1000="Pendiente");"") | D3: =FILTER(TRANSACCIONES!E3:E1000;(TRANSACCIONES!C3:C1000="CxC")*(TRANSACCIONES!M3:M1000="Pendiente");"") | E3: =FILTER(TRANSACCIONES!G3:G1000;(TRANSACCIONES!C3:C1000="CxC")*(TRANSACCIONES!M3:M1000="Pendiente");"") | F3: =FILTER(TRANSACCIONES!M3:M1000;(TRANSACCIONES!C3:C1000="CxC")*(TRANSACCIONES!M3:M1000="Pendiente");"") | G3: =FILTER(TRANSACCIONES!S3:S1000;(TRANSACCIONES!C3:C1000="CxC")*(TRANSACCIONES!M3:M1000="Pendiente");"") | H3: =FILTER(TRANSACCIONES!T3:T1000;(TRANSACCIONES!C3:C1000="CxC")*(TRANSACCIONES!M3:M1000="Pendiente");"") | I3: =FILTER(TRANSACCIONES!N3:N1000;(TRANSACCIONES!C3:C1000="CxC")*(TRANSACCIONES!M3:M1000="Pendiente");"") | J3: =FILTER(TRANSACCIONES!U3:U1000;(TRANSACCIONES!C3:C1000="CxC")*(TRANSACCIONES!M3:M1000="Pendiente");"") | K3: =FILTER(TRANSACCIONES!W3:W1000;(TRANSACCIONES!C3:C1000="CxC")*(TRANSACCIONES!M3:M1000="Pendiente");"")

Sheet FLUJO_CAJA
A1: FLUJO DE CAJA
A2: Mes | B2: Ingresos USD | C2: Gastos USD | D2: Flujo Neto | E2: Acumulado

Sheet IVA_CONTROL
A1: CONTROL IVA 13%
A2: Fecha | B2: Entidad | C2: Monto Base | D2: IVA Aplicable | E2: Tipo
D3: =IF(AND(TRANSACCIONES!I3="Sí",NOT(OR(B3=CONFIG!$B$10,B3=CONFIG!$B$11))),C3*0.13,0)

Sheet TARJETAS
A1: CONTROL TARJETAS CRÉDITO
A2: Tarjeta | B2: Saldo Actual | C2: Día Corte | D2: Días hasta corte | E2: Próxima fecha | F2: Pagos mes

Sheet CONCILIACION
A1: CONCILIACIÓN BANCARIA
A5: Saldo según banco:
A6: Menos: Cheques en tránsito
A7: Más: Depósitos en tránsito
A8: =Saldo ajustado banco
A12: Saldo según libros:
A13: Menos: Cargos bancarios
A14: Más: Intereses
A15: =Saldo ajustado libros
A19: Diferencia: | B19: =B8-B15

Sheet PERSONAL_VS_NEGOCIO
A1: PERSONAL VS NEGOCIO
A2: Tipo | B2: Ingresos | C2: Gastos | D2: Balance
A3: PERSONAL | B3: =SUMIFS(TRANSACCIONES!F:F,TRANSACCIONES!P:P,"Personal",TRANSACCIONES!C:C,"Ingreso") | C3: =SUMIFS(TRANSACCIONES!F:F,TRANSACCIONES!P:P,"Personal",TRANSACCIONES!C:C,"Gasto") | D3: =B3-C3
A4: NEGOCIO
A5: TOTAL

Sheet CATEGORIAS
A1: ANÁLISIS POR CATEGORÍA
A2: Categoría | B2: Total Gastado | C2: % del Total | D2: # Transacciones | E2: Promedio

Sheet PROYECTOS
A1: ANÁLISIS POR PROYECTO
A2: Proyecto | B2: Total Gastado | C2: % del Total | D2: # Transacciones | E2: Promedio

Sheet PROVEEDORES
A1: ANÁLISIS PROVEEDORES
A2: Proveedor | B2: Total Comprado | C2: # Facturas | D2: Promedio | E2: Última Compra | F2: Días desde

Sheet CLIENTES
A1: ANÁLISIS CLIENTES
A2: Cliente | B2: Total Vendido | C2: # Facturas | D2: Promedio | E2: Última Venta | F2: Días desde

Sheet AUDITORIA
A1: AUDITORÍA Y DETECCIÓN DE ANOMALÍAS
A2: Tipo | B2: Fila | C2: Campo | D2: Problema | E2: Valor Actual | F2: Acción Sugerida

Sheet CIERRE_MENSUAL
A1: CIERRE MENSUAL
A3: CHECKLIST - Completar antes de cerrar mes
A5: ☐ 1. Registrar TODAS las facturas del mes
A6: ☐ 2. Actualizar tipo de cambio al último día del mes
A7: ☐ 3. Conciliar bancos (hoja CONCILIACION)
A8: ☐ 4. Revisar CxP/CxC pendientes
A9: ☐ 5. Generar asientos de ajuste (si aplica)
A10: ☐ 6. Validar que columna R en TRANSACCIONES = '✓ OK'
A11: ☐ 7. Actualizar 'Mes Actual' en CONFIG (B13)
A12: ☐ 8. Actualizar 'Último Cierre' en CONFIG (B14)
A13: ☐ 9. Registrar histórico TC en HISTORICO_TC
A14: ☐ 10. Revisar dashboard RESUMEN
A16: SALDOS A ARRASTRAR AL PRÓXIMO MES
A18: Total CxP a arrastrar: | B18: =SUM(CxP!H3:H1000)
A19: Total CxC a arrastrar: | B19: =SUM(CxC!H3:H1000)
A20: Saldo efectivo: | B20: =BALANCE_GENERAL!B5
A21: Utilidad neta mes: | B21: =ESTADO_RESULTADOS!B40
A23: HISTÓRICO DE CIERRES MENSUALES
A24: Mes | B24: Ingresos | C24: Gastos | D24: Utilidad | E24: CxP | F24: CxC | G24: Efectivo | H24: Margen %

Sheet HISTORICO_TC
A1: HISTÓRICO DE TIPO DE CAMBIO USD → CRC
A2: ⚠️ Registrar TC al finalizar cada mes - Crítico para notas de crédito retroactivas
A3: Fecha Efectiva | B3: TC Compra | C3: TC Venta | D3: TC Promedio | E3: Fuente | F3: Registrado Por | G3: Notas
A4: 45978 | B4: 539 | C4: 541 | D4: =(B4+C4)/2 | E4: BCCR | F4: Sistema | G4: TC actual
A5: 45962 | B5: 538 | C5: 540 | D5: =(B5+C5)/2 | E5: BCCR | F5: Sistema | G5: Inicio noviembre
A6: 45931 | B6: 535 | C6: 537 | D6: =(B6+C6)/2 | E6: BCCR | F6: Sistema | G6: Inicio octubre

Sheet ASIENTOS_AJUSTE
A1: ASIENTOS DE AJUSTE
A2: Registrar aquí ajustes que NO son transacciones normales
A3: Fecha Ajuste | B3: Tipo de Ajuste | C3: Referencia | D3: Cuenta Afectada | E3: Monto Original | F3: Monto Ajustado | G3: Diferencia | H3: Moneda | I3: TC Usado | J3: Explicación | K3: Aprobado Por | L3: Fecha Aprobación
A4: 45991 | B4: Diferencia TC | C4: Factura #123 | D4: CxP - Proveedor XYZ | E4: 540000 | F4: 550000 | G4: =F4-E4 | H4: CRC | I4: 550 | J4: Ajuste por cambio TC noviembre (540→550) | K4: Alvaro Velasco | L4: 45991

Sheet BALANCE_GENERAL
A1: BALANCE GENERAL / ESTADO SITUACIÓN FINANCIERA
A2: Al 17 de November, 2025
A4: ACTIVO CORRIENTE
A5: Efectivo y equivalentes | B5: =SUMIFS(TRANSACCIONES!F:F,TRANSACCIONES!C:C,"Ingreso",TRANSACCIONES!M:M,"Cobrado",TRANSACCIONES!E:E,"USD")-SUMIFS(TRANSACCIONES!F:F,TRANSACCIONES!C:C,"Gasto",TRANSACCIONES!M:M,"Pagado",TRANSACCIONES!E:E,"USD")
A6: Cuentas por Cobrar (CxC) | B6: =SUM(CxC!H3:H1000)
A7: Inventario | B7: =SUMIFS(TRANSACCIONES!F:F,TRANSACCIONES!C:C,"Inventario",TRANSACCIONES!E:E,"USD")
A8: Total Activo Corriente | B8: =SUM(B5:B7)
A10: ACTIVO NO CORRIENTE
A11: Propiedad, Planta y Equipo | B11: 0
A12: Menos: Depreciación Acumulada | B12: 0
A13: Activos Intangibles | B13: 0
A14: Total Activo No Corriente | B14: =SUM(B11:B13)
A16: TOTAL ACTIVOS | B16: =B8+B14
A18: PASIVO CORRIENTE
A19: Cuentas por Pagar (CxP) | B19: =SUM(CxP!H3:H1000)
A20: Tarjetas de Crédito | B20: =SUMIFS(TRANSACCIONES!F:F,TRANSACCIONES!C:C,"CxP",TRANSACCIONES!D:D,"Tarjeta Crédito",TRANSACCIONES!M:M,"Pendiente",TRANSACCIONES!E:E,"USD")
A21: Impuestos por Pagar (IVA) | B21: =SUMIFS(IVA_CONTROL!D:D,IVA_CONTROL!E:E,"Venta")-SUMIFS(IVA_CONTROL!D:D,IVA_CONTROL!E:E,"Compra")
A22: Total Pasivo Corriente | B22: =SUM(B19:B21)
A24: PASIVO NO CORRIENTE
A25: Préstamos largo plazo | B25: 0
A26: Total Pasivo No Corriente | B26: =B25
A28: TOTAL PASIVOS | B28: =B22+B26
A30: PATRIMONIO
A31: Capital Social | B31: 10000
A32: Utilidades Retenidas | B32: 0
A33: Utilidad del Ejercicio | B33: =ESTADO_RESULTADOS!B40
A34: Total Patrimonio | B34: =SUM(B31:B33)
A36: TOTAL PASIVO + PATRIMONIO | B36: =B28+B34
A38: VERIFICACIÓN (Debe ser 0): | B38: =B16-B36

Sheet ESTADO_RESULTADOS
A1: ESTADO DE RESULTADOS (P&L)
A2: Del 01 al 30 de Noviembre, 2025
A4: INGRESOS
A5: Ingresos por Ventas | B5: =SUMIFS(TRANSACCIONES!F:F,TRANSACCIONES!C:C,"Ingreso",TRANSACCIONES!E:E,"USD")
A6: Ingresos por Servicios | B6: =SUMIFS(TRANSACCIONES!F:F,TRANSACCIONES!C:C,"Servicios",TRANSACCIONES!E:E,"USD")
A7: Otros Ingresos | B7: 0
A8: Total Ingresos | B8: =SUM(B5:B7)
A10: COSTO DE VENTAS
A11: Costo Producto Vendido | B11: =SUMIFS(TRANSACCIONES!F:F,TRANSACCIONES!C:C,"Inventario",TRANSACCIONES!E:E,"USD")
A12: Mano de Obra Directa | B12: 0
A13: Total Costo Ventas | B13: =SUM(B11:B12)
A15: UTILIDAD BRUTA | B15: =B8-B13
A16: Margen Bruto % | B16: =IFERROR(B15/B8*100,0)
A18: GASTOS OPERACIONALES
A19: Gastos Administrativos | B19: =SUMIFS(TRANSACCIONES!F:F,TRANSACCIONES!C:C,"Gasto",TRANSACCIONES!E:E,"USD")
A20: Gastos de Ventas | B20: 0
A21: Gastos de Marketing | B21: =SUMIFS(TRANSACCIONES!F:F,TRANSACCIONES!C:C,"Marketing",TRANSACCIONES!E:E,"USD")
A22: Otros Gastos | B22: 0
A23: Total Gastos Operacionales | B23: =SUM(B19:B22)
A25: EBITDA | B25: =B15-B23
A27: Depreciación y Amortización | B27: 0
A29: EBIT (Utilidad Operacional) | B29: =B25-B27
A31: GASTOS FINANCIEROS
A32: Intereses Tarjetas | B32: 0
A33: Intereses Préstamos | B33: 0
A34: Total Gastos Financieros | B34: =SUM(B32:B33)
A36: UTILIDAD ANTES IMPUESTOS | B36: =B29-B34
A38: Impuesto Renta (30% est) | B38: =B36*0.30
A40: UTILIDAD NETA | B40: =B36-B38
A41: Margen Neto % | B41: =IFERROR(B40/B8*100,0)

Sheet INSTRUCCIONES
A1: GUÍA DE USO DEL SISTEMA ERP v5.0
A3: ÍNDICE DE INSTRUCCIONES
A4: 1. Cómo registrar una transacción
A5: 2. Cómo hacer cierre mensual
A6: 3. Cómo ajustar diferencias de tipo de cambio
A7: 4. Cómo registrar nota de crédito/débito
A8: 5. Cómo registrar pagos parciales
A9: 6. Cómo usar zona franca (exención IVA)
A10: 7. Cómo interpretar el dashboard (RESUMEN)
A11: 8. Cómo conciliar bancos
A14: 1. CÓMO REGISTRAR UNA TRANSACCIÓN
A16: Paso 1: Ir a hoja TRANSACCIONES
... A62: Paso 3: Aprobar y fechar
